Workbook

Sheet DATOS REVISADOS
C1: PROCESAMIENTO DE EQUIPOS AUTOMATICOS CALIDAD DE AIRE | G1: Codigo: FO-PO-PSM-66-06
G2: Versiòn: 01
G3: Fecha : 26/08/2023
A4: Fecha | B4: #HHMM | C4: PM10 µg/m³ | D4: PM2.5 µg/m³ | E4: SO2 ppb | F4: NO ppb | G4: NO2 ppb | H4: NOX ppb
B5: 0
B6: 0.0069444444
B7: 0.013888889
B8: 0.020833333
B9: 0.027777778
B10: 0.034722222
B11: 0.041666667
B12: 0.048611111
B13: 0.055555556
B14: 0.0625
B15: 0.069444444
B16: 0.076388889
... B4612: 1.9930556

Sheet MET
A1: Date | B1: Time | C1: Temp | D1: Presion

Sheet DATOS X HORA
C1: ='DATOS REVISADOS'!C1:F3 -> PROCESAMIENTO DE EQUIPOS AUTOMATICOS CALIDAD DE AIRE | I1: Codigo: FO-PO-PSM-66-06
I2: Versiòn: 01
I3: Fecha : 26/08/2023
A4: Fecha | B4: #HHMM | C4: ='DATOS REVISADOS'!C4 -> PM10 µg/m³ | D4: ='DATOS REVISADOS'!D4 -> PM2.5 µg/m³ | E4: ='DATOS REVISADOS'!E4 -> SO2 ppb | F4: CO ppm | G4: O3 µg/m³ | H4: NO ppb | I4: NO2 ppb | J4: NOX ppb
B5: 3.7470027e-16 | C5: =IFERROR(AVERAGE(OFFSET('DATOS REVISADOS'!$C$5,(((ROW()-9)*6)+6)+18,0,6,1)),"-") -> - | D5: =IFERROR(AVERAGE(OFFSET('DATOS REVISADOS'!$D$5,(((ROW()-9)*6)+6)+18,0,6,1)),"-") -> - | E5: =IFERROR(AVERAGE(OFFSET('DATOS REVISADOS'!$E$5,(((ROW()-9)*6)+6)+18,0,6,1)),"-") -> - | H5: =IFERROR(AVERAGE(OFFSET('DATOS REVISADOS'!$F$5,(((ROW()-9)*6)+6)+18,0,6,1)),"-") -> - | I5: =IFERROR(AVERAGE(OFFSET('DATOS REVISADOS'!$G$5,(((ROW()-9)*6)+6)+18,0,6,1)),"-") -> - | J5: =+H5+I5 -> #VALUE!
B6: 0.041666667 | C6: =IFERROR(AVERAGE(OFFSET('DATOS REVISADOS'!$C$5,(((ROW()-9)*6)+6)+18,0,6,1)),"-") -> - | D6: =IFERROR(AVERAGE(OFFSET('DATOS REVISADOS'!$D$5,(((ROW()-9)*6)+6)+18,0,6,1)),"-") -> - | E6: =IFERROR(AVERAGE(OFFSET('DATOS REVISADOS'!$E$5,(((ROW()-9)*6)+6)+18,0,6,1)),"-") -> - | H6: =IFERROR(AVERAGE(OFFSET('DATOS REVISADOS'!$F$5,(((ROW()-9)*6)+6)+18,0,6,1)),"-") -> - | I6: =IFERROR(AVERAGE(OFFSET('DATOS REVISADOS'!$G$5,(((ROW()-9)*6)+6)+18,0,6,1)),"-") -> - | J6: =+H6+I6 -> #VALUE!
B7: =+$B$6+B6 -> 0.083333333 | C7: =IFERROR(AVERAGE(OFFSET('DATOS REVISADOS'!$C$5,(((ROW()-9)*6)+6)+18,0,6,1)),"-") -> - | D7: =IFERROR(AVERAGE(OFFSET('DATOS REVISADOS'!$D$5,(((ROW()-9)*6)+6)+18,0,6,1)),"-") -> - | E7: =IFERROR(AVERAGE(OFFSET('DATOS REVISADOS'!$E$5,(((ROW()-9)*6)+6)+18,0,6,1)),"-") -> - | H7: =IFERROR(AVERAGE(OFFSET('DATOS REVISADOS'!$F$5,(((ROW()-9)*6)+6)+18,0,6,1)),"-") -> - | I7: =IFERROR(AVERAGE(OFFSET('DATOS REVISADOS'!$G$5,(((ROW()-9)*6)+6)+18,0,6,1)),"-") -> - | J7: =+H7+I7 -> #VALUE!
B8: =+$B$6+B7 -> 0.125 | C8: =IFERROR(AVERAGE(OFFSET('DATOS REVISADOS'!$C$5,(((ROW()-9)*6)+6)+18,0,6,1)),"-") -> - | D8: =IFERROR(AVERAGE(OFFSET('DATOS REVISADOS'!$D$5,(((ROW()-9)*6)+6)+18,0,6,1)),"-") -> - | E8: =IFERROR(AVERAGE(OFFSET('DATOS REVISADOS'!$E$5,(((ROW()-9)*6)+6)+18,0,6,1)),"-") -> - | H8: =IFERROR(AVERAGE(OFFSET('DATOS REVISADOS'!$F$5,(((ROW()-9)*6)+6)+18,0,6,1)),"-") -> - | I8: =IFERROR(AVERAGE(OFFSET('DATOS REVISADOS'!$G$5,(((ROW()-9)*6)+6)+18,0,6,1)),"-") -> - | J8: =+H8+I8 -> #VALUE!
B9: =+$B$6+B8 -> 0.16666667 | C9: =IFERROR(AVERAGE(OFFSET('DATOS REVISADOS'!$C$5,(((ROW()-9)*6)+6)+18,0,6,1)),"-") -> - | D9: =IFERROR(AVERAGE(OFFSET('DATOS REVISADOS'!$D$5,(((ROW()-9)*6)+6)+18,0,6,1)),"-") -> - | E9: =IFERROR(AVERAGE(OFFSET('DATOS REVISADOS'!$E$5,(((ROW()-9)*6)+6)+18,0,6,1)),"-") -> - | H9: =IFERROR(AVERAGE(OFFSET('DATOS REVISADOS'!$F$5,(((ROW()-9)*6)+6)+18,0,6,1)),"-") -> - | I9: =IFERROR(AVERAGE(OFFSET('DATOS REVISADOS'!$G$5,(((ROW()-9)*6)+6)+18,0,6,1)),"-") -> - | J9: =+H9+I9 -> #VALUE!
B10: =+$B$6+B9 -> 0.20833333 | C10: =IFERROR(AVERAGE(OFFSET('DATOS REVISADOS'!$C$5,(((ROW()-9)*6)+6)+18,0,6,1)),"-") -> - | D10: =IFERROR(AVERAGE(OFFSET('DATOS REVISADOS'!$D$5,(((ROW()-9)*6)+6)+18,0,6,1)),"-") -> - | E10: =IFERROR(AVERAGE(OFFSET('DATOS REVISADOS'!$E$5,(((ROW()-9)*6)+6)+18,0,6,1)),"-") -> - | H10: =IFERROR(AVERAGE(OFFSET('DATOS REVISADOS'!$F$5,(((ROW()-9)*6)+6)+18,0,6,1)),"-") -> - | I10: =IFERROR(AVERAGE(OFFSET('DATOS REVISADOS'!$G$5,(((ROW()-9)*6)+6)+18,0,6,1)),"-") -> - | J10: =+H10+I10 -> #VALUE!
B11: =+$B$6+B10 -> 0.25 | C11: =IFERROR(AVERAGE(OFFSET('DATOS REVISADOS'!$C$5,(((ROW()-9)*6)+6)+18,0,6,1)),"-") -> - | D11: =IFERROR(AVERAGE(OFFSET('DATOS REVISADOS'!$D$5,(((ROW()-9)*6)+6)+18,0,6,1)),"-") -> - | E11: =IFERROR(AVERAGE(OFFSET('DATOS REVISADOS'!$E$5,(((ROW()-9)*6)+6)+18,0,6,1)),"-") -> - | H11: =IFERROR(AVERAGE(OFFSET('DATOS REVISADOS'!$F$5,(((ROW()-9)*6)+6)+18,0,6,1)),"-") -> - | I11: =IFERROR(AVERAGE(OFFSET('DATOS REVISADOS'!$G$5,(((ROW()-9)*6)+6)+18,0,6,1)),"-") -> - | J11: =+H11+I11 -> #VALUE!
B12: =+$B$6+B11 -> 0.29166667 | C12: =IFERROR(AVERAGE(OFFSET('DATOS REVISADOS'!$C$5,(((ROW()-9)*6)+6)+18,0,6,1)),"-") -> - | D12: =IFERROR(AVERAGE(OFFSET('DATOS REVISADOS'!$D$5,(((ROW()-9)*6)+6)+18,0,6,1)),"-") -> - | E12: =IFERROR(AVERAGE(OFFSET('DATOS REVISADOS'!$E$5,(((ROW()-9)*6)+6)+18,0,6,1)),"-") -> - | H12: =IFERROR(AVERAGE(OFFSET('DATOS REVISADOS'!$F$5,(((ROW()-9)*6)+6)+18,0,6,1)),"-") -> - | I12: =IFERROR(AVERAGE(OFFSET('DATOS REVISADOS'!$G$5,(((ROW()-9)*6)+6)+18,0,6,1)),"-") -> - | J12: =+H12+I12 -> #VALUE!
B13: =+$B$6+B12 -> 0.33333333 | C13: =IFERROR(AVERAGE(OFFSET('DATOS REVISADOS'!$C$5,(((ROW()-9)*6)+6)+18,0,6,1)),"-") -> - | D13: =IFERROR(AVERAGE(OFFSET('DATOS REVISADOS'!$D$5,(((ROW()-9)*6)+6)+18,0,6,1)),"-") -> - | E13: =IFERROR(AVERAGE(OFFSET('DATOS REVISADOS'!$E$5,(((ROW()-9)*6)+6)+18,0,6,1)),"-") -> - | H13: =IFERROR(AVERAGE(OFFSET('DATOS REVISADOS'!$F$5,(((ROW()-9)*6)+6)+18,0,6,1)),"-") -> - | I13: =IFERROR(AVERAGE(OFFSET('DATOS REVISADOS'!$G$5,(((ROW()-9)*6)+6)+18,0,6,1)),"-") -> - | J13: =+H13+I13 -> #VALUE!
B14: =+$B$6+B13 -> 0.375 | C14: =IFERROR(AVERAGE(OFFSET('DATOS REVISADOS'!$C$5,(((ROW()-9)*6)+6)+18,0,6,1)),"-") -> - | D14: =IFERROR(AVERAGE(OFFSET('DATOS REVISADOS'!$D$5,(((ROW()-9)*6)+6)+18,0,6,1)),"-") -> - | E14: =IFERROR(AVERAGE(OFFSET('DATOS REVISADOS'!$E$5,(((ROW()-9)*6)+6)+18,0,6,1)),"-") -> - | H14: =IFERROR(AVERAGE(OFFSET('DATOS REVISADOS'!$F$5,(((ROW()-9)*6)+6)+18,0,6,1)),"-") -> - | I14: =IFERROR(AVERAGE(OFFSET('DATOS REVISADOS'!$G$5,(((ROW()-9)*6)+6)+18,0,6,1)),"-") -> - | J14: =+H14+I14 -> #VALUE!
B15: =+$B$6+B14 -> 0.41666667 | C15: =IFERROR(AVERAGE(OFFSET('DATOS REVISADOS'!$C$5,(((ROW()-9)*6)+6)+18,0,6,1)),"-") -> - | D15: =IFERROR(AVERAGE(OFFSET('DATOS REVISADOS'!$D$5,(((ROW()-9)*6)+6)+18,0,6,1)),"-") -> - | E15: =IFERROR(AVERAGE(OFFSET('DATOS REVISADOS'!$E$5,(((ROW()-9)*6)+6)+18,0,6,1)),"-") -> - | H15: =IFERROR(AVERAGE(OFFSET('DATOS REVISADOS'!$F$5,(((ROW()-9)*6)+6)+18,0,6,1)),"-") -> - | I15: =IFERROR(AVERAGE(OFFSET('DATOS REVISADOS'!$G$5,(((ROW()-9)*6)+6)+18,0,6,1)),"-") -> - | J15: =+H15+I15 -> #VALUE!
B16: =+$B$6+B15 -> 0.45833333 | C16: =IFERROR(AVERAGE(OFFSET('DATOS REVISADOS'!$C$5,(((ROW()-9)*6)+6)+18,0,6,1)),"-") -> - | D16: =IFERROR(AVERAGE(OFFSET('DATOS REVISADOS'!$D$5,(((ROW()-9)*6)+6)+18,0,6,1)),"-") -> - | E16: =IFERROR(AVERAGE(OFFSET('DATOS REVISADOS'!$E$5,(((ROW()-9)*6)+6)+18,0,6,1)),"-") -> - | H16: =IFERROR(AVERAGE(OFFSET('DATOS REVISADOS'!$F$5,(((ROW()-9)*6)+6)+18,0,6,1)),"-") -> - | I16: =IFERROR(AVERAGE(OFFSET('DATOS REVISADOS'!$G$5,(((ROW()-9)*6)+6)+18,0,6,1)),"-") -> - | J16: =+H16+I16 -> #VALUE!
B17: =+$B$6+B16 -> 0.5 | C17: =IFERROR(AVERAGE(OFFSET('DATOS REVISADOS'!$C$5,(((ROW()-9)*6)+6)+18,0,6,1)),"-") -> - | D17: =IFERROR(AVERAGE(OFFSET('DATOS REVISADOS'!$D$5,(((ROW()-9)*6)+6)+18,0,6,1)),"-") -> - | E17: =IFERROR(AVERAGE(OFFSET('DATOS REVISADOS'!$E$5,(((ROW()-9)*6)+6)+18,0,6,1)),"-") -> - | H17: =IFERROR(AVERAGE(OFFSET('DATOS REVISADOS'!$F$5,(((ROW()-9)*6)+6)+18,0,6,1)),"-") -> - | I17: =IFERROR(AVERAGE(OFFSET('DATOS REVISADOS'!$G$5,(((ROW()-9)*6)+6)+18,0,6,1)),"-") -> - | J17: =+H17+I17 -> #VALUE!
B18: =+$B$6+B17 -> 0.54166667 | C18: =IFERROR(AVERAGE(OFFSET('DATOS REVISADOS'!$C$5,(((ROW()-9)*6)+6)+18,0,6,1)),"-") -> - | D18: =IFERROR(AVERAGE(OFFSET('DATOS REVISADOS'!$D$5,(((ROW()-9)*6)+6)+18,0,6,1)),"-") -> - | E18: =IFERROR(AVERAGE(OFFSET('DATOS REVISADOS'!$E$5,(((ROW()-9)*6)+6)+18,0,6,1)),"-") -> - | H18: =IFERROR(AVERAGE(OFFSET('DATOS REVISADOS'!$F$5,(((ROW()-9)*6)+6)+18,0,6,1)),"-") -> - | I18: =IFERROR(AVERAGE(OFFSET('DATOS REVISADOS'!$G$5,(((ROW()-9)*6)+6)+18,0,6,1)),"-") -> - | J18: =+H18+I18 -> #VALUE!
... B370: =+$B$6+B369 -> 15.208333 | C370: =IFERROR(AVERAGE(OFFSET('DATOS REVISADOS'!$C$5,(((ROW()-9)*6)+6)+18,0,6,1)),"-") -> - | D370: =IFERROR(AVERAGE(OFFSET('DATOS REVISADOS'!$D$5,(((ROW()-9)*6)+6)+18,0,6,1)),"-") -> - | E370: =IFERROR(AVERAGE(OFFSET('DATOS REVISADOS'!$E$5,(((ROW()-9)*6)+6)+18,0,6,1)),"-") -> - | H370: =IFERROR(AVERAGE(OFFSET('DATOS REVISADOS'!$F$5,(((ROW()-9)*6)+6)+18,0,6,1)),"-") -> - | I370: =IFERROR(AVERAGE(OFFSET('DATOS REVISADOS'!$G$5,(((ROW()-9)*6)+6)+18,0,6,1)),"-") -> - | J370: =+H370+I370 -> #VALUE!
B371: =+$B$6+B370 -> 15.25 | C371: =IFERROR(AVERAGE(OFFSET('DATOS REVISADOS'!$C$5,(((ROW()-9)*6)+6)+18,0,6,1)),"-") -> - | D371: =IFERROR(AVERAGE(OFFSET('DATOS REVISADOS'!$D$5,(((ROW()-9)*6)+6)+18,0,6,1)),"-") -> - | E371: =IFERROR(AVERAGE(OFFSET('DATOS REVISADOS'!$E$5,(((ROW()-9)*6)+6)+18,0,6,1)),"-") -> - | H371: =IFERROR(AVERAGE(OFFSET('DATOS REVISADOS'!$F$5,(((ROW()-9)*6)+6)+18,0,6,1)),"-") -> - | I371: =IFERROR(AVERAGE(OFFSET('DATOS REVISADOS'!$G$5,(((ROW()-9)*6)+6)+18,0,6,1)),"-") -> -
B372: =+$B$6+B371 -> 15.291667 | C372: =IFERROR(AVERAGE(OFFSET('DATOS REVISADOS'!$C$5,(((ROW()-9)*6)+6)+18,0,6,1)),"-") -> - | D372: =IFERROR(AVERAGE(OFFSET('DATOS REVISADOS'!$D$5,(((ROW()-9)*6)+6)+18,0,6,1)),"-") -> - | E372: =IFERROR(AVERAGE(OFFSET('DATOS REVISADOS'!$E$5,(((ROW()-9)*6)+6)+18,0,6,1)),"-") -> - | H372: =IFERROR(AVERAGE(OFFSET('DATOS REVISADOS'!$F$5,(((ROW()-9)*6)+6)+18,0,6,1)),"-") -> - | I372: =IFERROR(AVERAGE(OFFSET('DATOS REVISADOS'!$G$5,(((ROW()-9)*6)+6)+18,0,6,1)),"-") -> - | J372: =+H372+I372 -> #VALUE!
B373: =+$B$6+B372 -> 15.333333 | C373: =IFERROR(AVERAGE(OFFSET('DATOS REVISADOS'!$C$5,(((ROW()-9)*6)+6)+18,0,6,1)),"-") -> - | D373: =IFERROR(AVERAGE(OFFSET('DATOS REVISADOS'!$D$5,(((ROW()-9)*6)+6)+18,0,6,1)),"-") -> - | E373: =IFERROR(AVERAGE(OFFSET('DATOS REVISADOS'!$E$5,(((ROW()-9)*6)+6)+18,0,6,1)),"-") -> - | H373: =IFERROR(AVERAGE(OFFSET('DATOS REVISADOS'!$F$5,(((ROW()-9)*6)+6)+18,0,6,1)),"-") -> - | I373: =IFERROR(AVERAGE(OFFSET('DATOS REVISADOS'!$G$5,(((ROW()-9)*6)+6)+18,0,6,1)),"-") -> - | J373: =+H373+I373 -> #VALUE!
B374: =+$B$6+B373 -> 15.375 | C374: =IFERROR(AVERAGE(OFFSET('DATOS REVISADOS'!$C$5,(((ROW()-9)*6)+6)+18,0,6,1)),"-") -> - | D374: =IFERROR(AVERAGE(OFFSET('DATOS REVISADOS'!$D$5,(((ROW()-9)*6)+6)+18,0,6,1)),"-") -> - | E374: =IFERROR(AVERAGE(OFFSET('DATOS REVISADOS'!$E$5,(((ROW()-9)*6)+6)+18,0,6,1)),"-") -> - | H374: =IFERROR(AVERAGE(OFFSET('DATOS REVISADOS'!$F$5,(((ROW()-9)*6)+6)+18,0,6,1)),"-") -> - | I374: =IFERROR(AVERAGE(OFFSET('DATOS REVISADOS'!$G$5,(((ROW()-9)*6)+6)+18,0,6,1)),"-") -> - | J374: =+H374+I374 -> #VALUE!
B375: =+$B$6+B374 -> 15.416667 | C375: =IFERROR(AVERAGE(OFFSET('DATOS REVISADOS'!$C$5,(((ROW()-9)*6)+6)+18,0,6,1)),"-") -> - | D375: =IFERROR(AVERAGE(OFFSET('DATOS REVISADOS'!$D$5,(((ROW()-9)*6)+6)+18,0,6,1)),"-") -> - | E375: =IFERROR(AVERAGE(OFFSET('DATOS REVISADOS'!$E$5,(((ROW()-9)*6)+6)+18,0,6,1)),"-") -> - | H375: =IFERROR(AVERAGE(OFFSET('DATOS REVISADOS'!$F$5,(((ROW()-9)*6)+6)+18,0,6,1)),"-") -> - | I375: =IFERROR(AVERAGE(OFFSET('DATOS REVISADOS'!$G$5,(((ROW()-9)*6)+6)+18,0,6,1)),"-") -> - | J375: =+H375+I375 -> #VALUE!
B376: =+$B$6+B375 -> 15.458333 | C376: =IFERROR(AVERAGE(OFFSET('DATOS REVISADOS'!$C$5,(((ROW()-9)*6)+6)+18,0,6,1)),"-") -> - | D376: =IFERROR(AVERAGE(OFFSET('DATOS REVISADOS'!$D$5,(((ROW()-9)*6)+6)+18,0,6,1)),"-") -> - | E376: =IFERROR(AVERAGE(OFFSET('DATOS REVISADOS'!$E$5,(((ROW()-9)*6)+6)+18,0,6,1)),"-") -> - | H376: =IFERROR(AVERAGE(OFFSET('DATOS REVISADOS'!$F$5,(((ROW()-9)*6)+6)+18,0,6,1)),"-") -> - | I376: =IFERROR(AVERAGE(OFFSET('DATOS REVISADOS'!$G$5,(((ROW()-9)*6)+6)+18,0,6,1)),"-") -> - | J376: =+H376+I376 -> #VALUE!
B377: =+$B$6+B376 -> 15.5 | C377: =IFERROR(AVERAGE(OFFSET('DATOS REVISADOS'!$C$5,(((ROW()-9)*6)+6)+18,0,6,1)),"-") -> - | D377: =IFERROR(AVERAGE(OFFSET('DATOS REVISADOS'!$D$5,(((ROW()-9)*6)+6)+18,0,6,1)),"-") -> - | E377: =IFERROR(AVERAGE(OFFSET('DATOS REVISADOS'!$E$5,(((ROW()-9)*6)+6)+18,0,6,1)),"-") -> - | H377: =IFERROR(AVERAGE(OFFSET('DATOS REVISADOS'!$F$5,(((ROW()-9)*6)+6)+18,0,6,1)),"-") -> - | I377: =IFERROR(AVERAGE(OFFSET('DATOS REVISADOS'!$G$5,(((ROW()-9)*6)+6)+18,0,6,1)),"-") -> - | J377: =+H377+I377 -> #VALUE!
B378: =+$B$6+B377 -> 15.541667 | C378: =IFERROR(AVERAGE(OFFSET('DATOS REVISADOS'!$C$5,(((ROW()-9)*6)+6)+18,0,6,1)),"-") -> - | D378: =IFERROR(AVERAGE(OFFSET('DATOS REVISADOS'!$D$5,(((ROW()-9)*6)+6)+18,0,6,1)),"-") -> - | E378: =IFERROR(AVERAGE(OFFSET('DATOS REVISADOS'!$E$5,(((ROW()-9)*6)+6)+18,0,6,1)),"-") -> - | H378: =IFERROR(AVERAGE(OFFSET('DATOS REVISADOS'!$F$5,(((ROW()-9)*6)+6)+18,0,6,1)),"-") -> - | I378: =IFERROR(AVERAGE(OFFSET('DATOS REVISADOS'!$G$5,(((ROW()-9)*6)+6)+18,0,6,1)),"-") -> - | J378: =+H378+I378 -> #VALUE!
B379: =+$B$6+B378 -> 15.583333 | C379: =IFERROR(AVERAGE(OFFSET('DATOS REVISADOS'!$C$5,(((ROW()-9)*6)+6)+18,0,6,1)),"-") -> - | D379: =IFERROR(AVERAGE(OFFSET('DATOS REVISADOS'!$D$5,(((ROW()-9)*6)+6)+18,0,6,1)),"-") -> - | E379: =IFERROR(AVERAGE(OFFSET('DATOS REVISADOS'!$E$5,(((ROW()-9)*6)+6)+18,0,6,1)),"-") -> - | H379: =IFERROR(AVERAGE(OFFSET('DATOS REVISADOS'!$F$5,(((ROW()-9)*6)+6)+18,0,6,1)),"-") -> - | I379: =IFERROR(AVERAGE(OFFSET('DATOS REVISADOS'!$G$5,(((ROW()-9)*6)+6)+18,0,6,1)),"-") -> - | J379: =+H379+I379 -> #VALUE!
B380: =+$B$6+B379 -> 15.625 | C380: =IFERROR(AVERAGE(OFFSET('DATOS REVISADOS'!$C$5,(((ROW()-9)*6)+6)+18,0,6,1)),"-") -> - | D380: =IFERROR(AVERAGE(OFFSET('DATOS REVISADOS'!$D$5,(((ROW()-9)*6)+6)+18,0,6,1)),"-") -> - | E380: =IFERROR(AVERAGE(OFFSET('DATOS REVISADOS'!$E$5,(((ROW()-9)*6)+6)+18,0,6,1)),"-") -> - | H380: =IFERROR(AVERAGE(OFFSET('DATOS REVISADOS'!$F$5,(((ROW()-9)*6)+6)+18,0,6,1)),"-") -> - | I380: =IFERROR(AVERAGE(OFFSET('DATOS REVISADOS'!$G$5,(((ROW()-9)*6)+6)+18,0,6,1)),"-") -> - | J380: =+H380+I380 -> #VALUE!
B381: =+$B$6+B380 -> 15.666667 | C381: =IFERROR(AVERAGE(OFFSET('DATOS REVISADOS'!$C$5,(((ROW()-9)*6)+6)+18,0,6,1)),"-") -> - | D381: =IFERROR(AVERAGE(OFFSET('DATOS REVISADOS'!$D$5,(((ROW()-9)*6)+6)+18,0,6,1)),"-") -> - | E381: =IFERROR(AVERAGE(OFFSET('DATOS REVISADOS'!$E$5,(((ROW()-9)*6)+6)+18,0,6,1)),"-") -> - | H381: =IFERROR(AVERAGE(OFFSET('DATOS REVISADOS'!$F$5,(((ROW()-9)*6)+6)+18,0,6,1)),"-") -> - | I381: =IFERROR(AVERAGE(OFFSET('DATOS REVISADOS'!$G$5,(((ROW()-9)*6)+6)+18,0,6,1)),"-") -> - | J381: =+H381+I381 -> #VALUE!
B382: =+$B$6+B381 -> 15.708333 | C382: =IFERROR(AVERAGE(OFFSET('DATOS REVISADOS'!$C$5,(((ROW()-9)*6)+6)+18,0,6,1)),"-") -> - | D382: =IFERROR(AVERAGE(OFFSET('DATOS REVISADOS'!$D$5,(((ROW()-9)*6)+6)+18,0,6,1)),"-") -> - | E382: =IFERROR(AVERAGE(OFFSET('DATOS REVISADOS'!$E$5,(((ROW()-9)*6)+6)+18,0,6,1)),"-") -> - | H382: =IFERROR(AVERAGE(OFFSET('DATOS REVISADOS'!$F$5,(((ROW()-9)*6)+6)+18,0,6,1)),"-") -> - | I382: =IFERROR(AVERAGE(OFFSET('DATOS REVISADOS'!$G$5,(((ROW()-9)*6)+6)+18,0,6,1)),"-") -> - | J382: =+H382+I382 -> #VALUE!
B383: =+$B$6+B382 -> 15.75 | C383: =IFERROR(AVERAGE(OFFSET('DATOS REVISADOS'!$C$5,(((ROW()-9)*6)+6)+18,0,6,1)),"-") -> - | D383: =IFERROR(AVERAGE(OFFSET('DATOS REVISADOS'!$D$5,(((ROW()-9)*6)+6)+18,0,6,1)),"-") -> - | E383: =IFERROR(AVERAGE(OFFSET('DATOS REVISADOS'!$E$5,(((ROW()-9)*6)+6)+18,0,6,1)),"-") -> - | H383: =IFERROR(AVERAGE(OFFSET('DATOS REVISADOS'!$F$5,(((ROW()-9)*6)+6)+18,0,6,1)),"-") -> - | I383: =IFERROR(AVERAGE(OFFSET('DATOS REVISADOS'!$G$5,(((ROW()-9)*6)+6)+18,0,6,1)),"-") -> - | J383: =+H383+I383 -> #VALUE!
... B772: =+$B$6+B771 -> 31.958333 | C772: =IFERROR(AVERAGE(OFFSET('DATOS REVISADOS'!$C$5,(((ROW()-9)*6)+6)+18,0,6,1)),"-") -> - | D772: =IFERROR(AVERAGE(OFFSET('DATOS REVISADOS'!$D$5,(((ROW()-9)*6)+6)+18,0,6,1)),"-") -> - | E772: =IFERROR(AVERAGE(OFFSET('DATOS REVISADOS'!$E$5,(((ROW()-9)*6)+6)+18,0,6,1)),"-") -> - | H772: =IFERROR(AVERAGE(OFFSET('DATOS REVISADOS'!$F$5,(((ROW()-9)*6)+6)+18,0,6,1)),"-") -> - | I772: =IFERROR(AVERAGE(OFFSET('DATOS REVISADOS'!$G$5,(((ROW()-9)*6)+6)+18,0,6,1)),"-") -> - | J772: =+H772+I772 -> #VALUE!

Sheet DATOS CORREGIDOS
D1: ='DATOS X HORA'!$C$1 -> PROCESAMIENTO DE EQUIPOS AUTOMATICOS CALIDAD DE AIRE | I1: Codigo: FO-PO-PSM-66-06
I2: Versiòn: 01
I3: Fecha : 26/08/2023
A4: RESULTADOS CORREGIDOS A CONDICIONES DE REFERENCIA
A5: Fecha | B5: #HHMM | C5: Temp,°C | D5: Presión,mmHg | E5: PM10 (µg/m³) | F5: PM2,5 (µg/m³) | G5: SO2 (µg/m³) | H5: CO (µg/m³) | I5: O3 (µg/m³) | J5: NO2 (µg/m³)
B6: =+'DATOS X HORA'!B5 -> 3.7470027e-16 | C6: =IFERROR(AVERAGE(OFFSET(MET!$C$2,(((ROW()-5)*2)+2)-4,0,2,1)),"-") -> - | D6: =IFERROR(AVERAGE(OFFSET(MET!$D$2,(((ROW()-5)*2)+2)-4,0,2,1)),"-") -> - | E6: =IFERROR(('DATOS X HORA'!C5)*((C6+273.15)*760)/(298.15*D6),"-") -> - | F6: =IFERROR(('DATOS X HORA'!D5)*((C6+273.15)*760)/(298.15*D6),"-") -> - | G6: =IFERROR(('DATOS X HORA'!E5*64.058/24.45)*((C6+273.15)*760)/(298.15*D6),"-") -> - | H6: =IFERROR((('DATOS X HORA'!F5*28.01/24.45)*1000)*((C6+273.15)*760)/(298.15*D6),"-") -> - | I6: =IFERROR((('DATOS X HORA'!G5)*((C6+273.15)*760)/(298.15*D6)),"-") -> - | J6: =IFERROR((('DATOS X HORA'!I5*46.005/24.45))*((C6+273.15)*760)/(298.15*D6),"-") -> -
B7: =+'DATOS X HORA'!B6 -> 0.041666667 | C7: =IFERROR(AVERAGE(OFFSET(MET!$C$2,(((ROW()-5)*2)+2)-4,0,2,1)),"-") -> - | D7: =IFERROR(AVERAGE(OFFSET(MET!$D$2,(((ROW()-5)*2)+2)-4,0,2,1)),"-") -> - | E7: =IFERROR(('DATOS X HORA'!C6)*((C7+273.15)*760)/(298.15*D7),"-") -> - | F7: =IFERROR(('DATOS X HORA'!D6)*((C7+273.15)*760)/(298.15*D7),"-") -> - | G7: =IFERROR(('DATOS X HORA'!E6*64.058/24.45)*((C7+273.15)*760)/(298.15*D7),"-") -> - | H7: =IFERROR((('DATOS X HORA'!F6*28.01/24.45)*1000)*((C7+273.15)*760)/(298.15*D7),"-") -> - | I7: =IFERROR((('DATOS X HORA'!G6)*((C7+273.15)*760)/(298.15*D7)),"-") -> - | J7: =IFERROR((('DATOS X HORA'!I6*46.005/24.45))*((C7+273.15)*760)/(298.15*D7),"-") -> -
B8: =+'DATOS X HORA'!B7 -> 0.083333333 | C8: =IFERROR(AVERAGE(OFFSET(MET!$C$2,(((ROW()-5)*2)+2)-4,0,2,1)),"-") -> - | D8: =IFERROR(AVERAGE(OFFSET(MET!$D$2,(((ROW()-5)*2)+2)-4,0,2,1)),"-") -> - | E8: =IFERROR(('DATOS X HORA'!C7)*((C8+273.15)*760)/(298.15*D8),"-") -> - | F8: =IFERROR(('DATOS X HORA'!D7)*((C8+273.15)*760)/(298.15*D8),"-") -> - | G8: =IFERROR(('DATOS X HORA'!E7*64.058/24.45)*((C8+273.15)*760)/(298.15*D8),"-") -> - | H8: =IFERROR((('DATOS X HORA'!F7*28.01/24.45)*1000)*((C8+273.15)*760)/(298.15*D8),"-") -> - | I8: =IFERROR((('DATOS X HORA'!G7)*((C8+273.15)*760)/(298.15*D8)),"-") -> - | J8: =IFERROR((('DATOS X HORA'!I7*46.005/24.45))*((C8+273.15)*760)/(298.15*D8),"-") -> -
B9: =+'DATOS X HORA'!B8 -> 0.125 | C9: =IFERROR(AVERAGE(OFFSET(MET!$C$2,(((ROW()-5)*2)+2)-4,0,2,1)),"-") -> - | D9: =IFERROR(AVERAGE(OFFSET(MET!$D$2,(((ROW()-5)*2)+2)-4,0,2,1)),"-") -> - | E9: =IFERROR(('DATOS X HORA'!C8)*((C9+273.15)*760)/(298.15*D9),"-") -> - | F9: =IFERROR(('DATOS X HORA'!D8)*((C9+273.15)*760)/(298.15*D9),"-") -> - | G9: =IFERROR(('DATOS X HORA'!E8*64.058/24.45)*((C9+273.15)*760)/(298.15*D9),"-") -> - | H9: =IFERROR((('DATOS X HORA'!F8*28.01/24.45)*1000)*((C9+273.15)*760)/(298.15*D9),"-") -> - | I9: =IFERROR((('DATOS X HORA'!G8)*((C9+273.15)*760)/(298.15*D9)),"-") -> - | J9: =IFERROR((('DATOS X HORA'!I8*46.005/24.45))*((C9+273.15)*760)/(298.15*D9),"-") -> -
B10: =+'DATOS X HORA'!B9 -> 0.16666667 | C10: =IFERROR(AVERAGE(OFFSET(MET!$C$2,(((ROW()-5)*2)+2)-4,0,2,1)),"-") -> - | D10: =IFERROR(AVERAGE(OFFSET(MET!$D$2,(((ROW()-5)*2)+2)-4,0,2,1)),"-") -> - | E10: =IFERROR(('DATOS X HORA'!C9)*((C10+273.15)*760)/(298.15*D10),"-") -> - | F10: =IFERROR(('DATOS X HORA'!D9)*((C10+273.15)*760)/(298.15*D10),"-") -> - | G10: =IFERROR(('DATOS X HORA'!E9*64.058/24.45)*((C10+273.15)*760)/(298.15*D10),"-") -> - | H10: =IFERROR((('DATOS X HORA'!F9*28.01/24.45)*1000)*((C10+273.15)*760)/(298.15*D10),"-") -> - | I10: =IFERROR((('DATOS X HORA'!G9)*((C10+273.15)*760)/(298.15*D10)),"-") -> - | J10: =IFERROR((('DATOS X HORA'!I9*46.005/24.45))*((C10+273.15)*760)/(298.15*D10),"-") -> -
B11: =+'DATOS X HORA'!B10 -> 0.20833333 | C11: =IFERROR(AVERAGE(OFFSET(MET!$C$2,(((ROW()-5)*2)+2)-4,0,2,1)),"-") -> - | D11: =IFERROR(AVERAGE(OFFSET(MET!$D$2,(((ROW()-5)*2)+2)-4,0,2,1)),"-") -> - | E11: =IFERROR(('DATOS X HORA'!C10)*((C11+273.15)*760)/(298.15*D11),"-") -> - | F11: =IFERROR(('DATOS X HORA'!D10)*((C11+273.15)*760)/(298.15*D11),"-") -> - | G11: =IFERROR(('DATOS X HORA'!E10*64.058/24.45)*((C11+273.15)*760)/(298.15*D11),"-") -> - | H11: =IFERROR((('DATOS X HORA'!F10*28.01/24.45)*1000)*((C11+273.15)*760)/(298.15*D11),"-") -> - | I11: =IFERROR((('DATOS X HORA'!G10)*((C11+273.15)*760)/(298.15*D11)),"-") -> - | J11: =IFERROR((('DATOS X HORA'!I10*46.005/24.45))*((C11+273.15)*760)/(298.15*D11),"-") -> -
B12: =+'DATOS X HORA'!B11 -> 0.25 | C12: =IFERROR(AVERAGE(OFFSET(MET!$C$2,(((ROW()-5)*2)+2)-4,0,2,1)),"-") -> - | D12: =IFERROR(AVERAGE(OFFSET(MET!$D$2,(((ROW()-5)*2)+2)-4,0,2,1)),"-") -> - | E12: =IFERROR(('DATOS X HORA'!C11)*((C12+273.15)*760)/(298.15*D12),"-") -> - | F12: =IFERROR(('DATOS X HORA'!D11)*((C12+273.15)*760)/(298.15*D12),"-") -> - | G12: =IFERROR(('DATOS X HORA'!E11*64.058/24.45)*((C12+273.15)*760)/(298.15*D12),"-") -> - | H12: =IFERROR((('DATOS X HORA'!F11*28.01/24.45)*1000)*((C12+273.15)*760)/(298.15*D12),"-") -> - | I12: =IFERROR((('DATOS X HORA'!G11)*((C12+273.15)*760)/(298.15*D12)),"-") -> - | J12: =IFERROR((('DATOS X HORA'!I11*46.005/24.45))*((C12+273.15)*760)/(298.15*D12),"-") -> -
B13: =+'DATOS X HORA'!B12 -> 0.29166667 | C13: =IFERROR(AVERAGE(OFFSET(MET!$C$2,(((ROW()-5)*2)+2)-4,0,2,1)),"-") -> - | D13: =IFERROR(AVERAGE(OFFSET(MET!$D$2,(((ROW()-5)*2)+2)-4,0,2,1)),"-") -> - | E13: =IFERROR(('DATOS X HORA'!C12)*((C13+273.15)*760)/(298.15*D13),"-") -> - | F13: =IFERROR(('DATOS X HORA'!D12)*((C13+273.15)*760)/(298.15*D13),"-") -> - | G13: =IFERROR(('DATOS X HORA'!E12*64.058/24.45)*((C13+273.15)*760)/(298.15*D13),"-") -> - | H13: =IFERROR((('DATOS X HORA'!F12*28.01/24.45)*1000)*((C13+273.15)*760)/(298.15*D13),"-") -> - | I13: =IFERROR((('DATOS X HORA'!G12)*((C13+273.15)*760)/(298.15*D13)),"-") -> - | J13: =IFERROR((('DATOS X HORA'!I12*46.005/24.45))*((C13+273.15)*760)/(298.15*D13),"-") -> -
B14: =+'DATOS X HORA'!B13 -> 0.33333333 | C14: =IFERROR(AVERAGE(OFFSET(MET!$C$2,(((ROW()-5)*2)+2)-4,0,2,1)),"-") -> - | D14: =IFERROR(AVERAGE(OFFSET(MET!$D$2,(((ROW()-5)*2)+2)-4,0,2,1)),"-") -> - | E14: =IFERROR(('DATOS X HORA'!C13)*((C14+273.15)*760)/(298.15*D14),"-") -> - | F14: =IFERROR(('DATOS X HORA'!D13)*((C14+273.15)*760)/(298.15*D14),"-") -> - | G14: =IFERROR(('DATOS X HORA'!E13*64.058/24.45)*((C14+273.15)*760)/(298.15*D14),"-") -> - | H14: =IFERROR((('DATOS X HORA'!F13*28.01/24.45)*1000)*((C14+273.15)*760)/(298.15*D14),"-") -> - | I14: =IFERROR((('DATOS X HORA'!G13)*((C14+273.15)*760)/(298.15*D14)),"-") -> - | J14: =IFERROR((('DATOS X HORA'!I13*46.005/24.45))*((C14+273.15)*760)/(298.15*D14),"-") -> -
B15: =+'DATOS X HORA'!B14 -> 0.375 | C15: =IFERROR(AVERAGE(OFFSET(MET!$C$2,(((ROW()-5)*2)+2)-4,0,2,1)),"-") -> - | D15: =IFERROR(AVERAGE(OFFSET(MET!$D$2,(((ROW()-5)*2)+2)-4,0,2,1)),"-") -> - | E15: =IFERROR(('DATOS X HORA'!C14)*((C15+273.15)*760)/(298.15*D15),"-") -> - | F15: =IFERROR(('DATOS X HORA'!D14)*((C15+273.15)*760)/(298.15*D15),"-") -> - | G15: =IFERROR(('DATOS X HORA'!E14*64.058/24.45)*((C15+273.15)*760)/(298.15*D15),"-") -> - | H15: =IFERROR((('DATOS X HORA'!F14*28.01/24.45)*1000)*((C15+273.15)*760)/(298.15*D15),"-") -> - | I15: =IFERROR((('DATOS X HORA'!G14)*((C15+273.15)*760)/(298.15*D15)),"-") -> - | J15: =IFERROR((('DATOS X HORA'!I14*46.005/24.45))*((C15+273.15)*760)/(298.15*D15),"-") -> -
B16: =+'DATOS X HORA'!B15 -> 0.41666667 | C16: =IFERROR(AVERAGE(OFFSET(MET!$C$2,(((ROW()-5)*2)+2)-4,0,2,1)),"-") -> - | D16: =IFERROR(AVERAGE(OFFSET(MET!$D$2,(((ROW()-5)*2)+2)-4,0,2,1)),"-") -> - | E16: =IFERROR(('DATOS X HORA'!C15)*((C16+273.15)*760)/(298.15*D16),"-") -> - | F16: =IFERROR(('DATOS X HORA'!D15)*((C16+273.15)*760)/(298.15*D16),"-") -> - | G16: =IFERROR(('DATOS X HORA'!E15*64.058/24.45)*((C16+273.15)*760)/(298.15*D16),"-") -> - | H16: =IFERROR((('DATOS X HORA'!F15*28.01/24.45)*1000)*((C16+273.15)*760)/(298.15*D16),"-") -> - | I16: =IFERROR((('DATOS X HORA'!G15)*((C16+273.15)*760)/(298.15*D16)),"-") -> - | J16: =IFERROR((('DATOS X HORA'!I15*46.005/24.45))*((C16+273.15)*760)/(298.15*D16),"-") -> -
B17: =+'DATOS X HORA'!B16 -> 0.45833333 | C17: =IFERROR(AVERAGE(OFFSET(MET!$C$2,(((ROW()-5)*2)+2)-4,0,2,1)),"-") -> - | D17: =IFERROR(AVERAGE(OFFSET(MET!$D$2,(((ROW()-5)*2)+2)-4,0,2,1)),"-") -> - | E17: =IFERROR(('DATOS X HORA'!C16)*((C17+273.15)*760)/(298.15*D17),"-") -> - | F17: =IFERROR(('DATOS X HORA'!D16)*((C17+273.15)*760)/(298.15*D17),"-") -> - | G17: =IFERROR(('DATOS X HORA'!E16*64.058/24.45)*((C17+273.15)*760)/(298.15*D17),"-") -> - | H17: =IFERROR((('DATOS X HORA'!F16*28.01/24.45)*1000)*((C17+273.15)*760)/(298.15*D17),"-") -> - | I17: =IFERROR((('DATOS X HORA'!G16)*((C17+273.15)*760)/(298.15*D17)),"-") -> - | J17: =IFERROR((('DATOS X HORA'!I16*46.005/24.45))*((C17+273.15)*760)/(298.15*D17),"-") -> -
... B773: =+'DATOS X HORA'!B772 -> 31.958333 | C773: =IFERROR(AVERAGE(OFFSET(MET!$C$2,(((ROW()-5)*2)+2)-4,0,2,1)),"-") -> - | D773: =IFERROR(AVERAGE(OFFSET(MET!$D$2,(((ROW()-5)*2)+2)-4,0,2,1)),"-") -> - | E773: =IFERROR(('DATOS X HORA'!C772)*((C773+273.15)*760)/(298.15*D773),"-") -> - | F773: =IFERROR(('DATOS X HORA'!D772)*((C773+273.15)*760)/(298.15*D773),"-") -> - | G773: =IFERROR(('DATOS X HORA'!E772*64.058/24.45)*((C773+273.15)*760)/(298.15*D773),"-") -> - | H773: =IFERROR((('DATOS X HORA'!F772*28.01/24.45)*1000)*((C773+273.15)*760)/(298.15*D773),"-") -> - | I773: =IFERROR((('DATOS X HORA'!G772)*((C773+273.15)*760)/(298.15*D773)),"-") -> - | J773: =IFERROR((('DATOS X HORA'!I772*46.005/24.45))*((C773+273.15)*760)/(298.15*D773),"-") -> -

Sheet COMPARACIÓN 24H
C1: ='DATOS CORREGIDOS'!D1 -> PROCESAMIENTO DE EQUIPOS AUTOMATICOS CALIDAD DE AIRE | I1: Codigo: FO-PO-PSM-66-06
I2: Versiòn: 01
I3: Fecha : 26/08/2023
A4: COMPARACION CON NORMA 24 HORAS
A5: FECHA | B5: PROMEDIOS 24 HORAS | E5: LÍMITES NORMATIVOS RES. 2254/2017
B6: PM10 (µg/m³) | C6: PM2,5 (µg/m³) | D6: SO2 (µg/m³) | E6: PM10 | G6: PM2,5 | I6: SO2
E7: Norma 24h | F7: Cumplimiento | G7: Norma 24h | H7: Cumplimiento | I7: Norma 24h | J7: Cumplimiento
A8: =IFERROR(AVERAGE(OFFSET('DATOS CORREGIDOS'!$A$6,(((ROW()-27)*24)+24)+432,0,24,1)),"") | B8: =IFERROR(AVERAGE(OFFSET('DATOS CORREGIDOS'!$E$6,(((ROW()-27)*24)+24)+432,0,24,1)),"") | C8: =IFERROR(AVERAGE(OFFSET('DATOS CORREGIDOS'!$F$6,(((ROW()-27)*24)+24)+432,0,24,1)),"") | D8: =IFERROR(AVERAGE(OFFSET('DATOS CORREGIDOS'!$G$6,(((ROW()-27)*24)+24)+432,0,24,1)),"") | E8: 75 | F8: =+IF(B8>E8,"NO","SÍ") -> NO | G8: 37 | H8: =+IF(C8>G8,"NO","SÍ") -> NO | I8: 50 | J8: =+IF(D8>I8,"NO","SÍ") -> NO
A9: =IFERROR(AVERAGE(OFFSET('DATOS CORREGIDOS'!$A$6,(((ROW()-27)*24)+24)+432,0,24,1)),"") | B9: =IFERROR(AVERAGE(OFFSET('DATOS CORREGIDOS'!$E$6,(((ROW()-27)*24)+24)+432,0,24,1)),"") | C9: =IFERROR(AVERAGE(OFFSET('DATOS CORREGIDOS'!$F$6,(((ROW()-27)*24)+24)+432,0,24,1)),"") | D9: =IFERROR(AVERAGE(OFFSET('DATOS CORREGIDOS'!$G$6,(((ROW()-27)*24)+24)+432,0,24,1)),"") | E9: 75 | F9: =+IF(B9>E9,"NO","SÍ") -> NO | G9: 37 | H9: =+IF(C9>G9,"NO","SÍ") -> NO | I9: 50 | J9: =+IF(D9>I9,"NO","SÍ") -> NO
A10: =IFERROR(AVERAGE(OFFSET('DATOS CORREGIDOS'!$A$6,(((ROW()-27)*24)+24)+432,0,24,1)),"") | B10: =IFERROR(AVERAGE(OFFSET('DATOS CORREGIDOS'!$E$6,(((ROW()-27)*24)+24)+432,0,24,1)),"") | C10: =IFERROR(AVERAGE(OFFSET('DATOS CORREGIDOS'!$F$6,(((ROW()-27)*24)+24)+432,0,24,1)),"") | D10: =IFERROR(AVERAGE(OFFSET('DATOS CORREGIDOS'!$G$6,(((ROW()-27)*24)+24)+432,0,24,1)),"") | E10: 75 | F10: =+IF(B10>E10,"NO","SÍ") -> NO | G10: 37 | H10: =+IF(C10>G10,"NO","SÍ") -> NO | I10: 50 | J10: =+IF(D10>I10,"NO","SÍ") -> NO
A11: =IFERROR(AVERAGE(OFFSET('DATOS CORREGIDOS'!$A$6,(((ROW()-27)*24)+24)+432,0,24,1)),"") | B11: =IFERROR(AVERAGE(OFFSET('DATOS CORREGIDOS'!$E$6,(((ROW()-27)*24)+24)+432,0,24,1)),"") | C11: =IFERROR(AVERAGE(OFFSET('DATOS CORREGIDOS'!$F$6,(((ROW()-27)*24)+24)+432,0,24,1)),"") | D11: =IFERROR(AVERAGE(OFFSET('DATOS CORREGIDOS'!$G$6,(((ROW()-27)*24)+24)+432,0,24,1)),"") | E11: 75 | F11: =+IF(B11>E11,"NO","SÍ") -> NO | G11: 37 | H11: =+IF(C11>G11,"NO","SÍ") -> NO | I11: 50 | J11: =+IF(D11>I11,"NO","SÍ") -> NO
A12: =IFERROR(AVERAGE(OFFSET('DATOS CORREGIDOS'!$A$6,(((ROW()-27)*24)+24)+432,0,24,1)),"") | B12: =IFERROR(AVERAGE(OFFSET('DATOS CORREGIDOS'!$E$6,(((ROW()-27)*24)+24)+432,0,24,1)),"") | C12: =IFERROR(AVERAGE(OFFSET('DATOS CORREGIDOS'!$F$6,(((ROW()-27)*24)+24)+432,0,24,1)),"") | D12: =IFERROR(AVERAGE(OFFSET('DATOS CORREGIDOS'!$G$6,(((ROW()-27)*24)+24)+432,0,24,1)),"") | E12: 75 | F12: =+IF(B12>E12,"NO","SÍ") -> NO | G12: 37 | H12: =+IF(C12>G12,"NO","SÍ") -> NO | I12: 50 | J12: =+IF(D12>I12,"NO","SÍ") -> NO
A13: =IFERROR(AVERAGE(OFFSET('DATOS CORREGIDOS'!$A$6,(((ROW()-27)*24)+24)+432,0,24,1)),"") | B13: =IFERROR(AVERAGE(OFFSET('DATOS CORREGIDOS'!$E$6,(((ROW()-27)*24)+24)+432,0,24,1)),"") | C13: =IFERROR(AVERAGE(OFFSET('DATOS CORREGIDOS'!$F$6,(((ROW()-27)*24)+24)+432,0,24,1)),"") | D13: =IFERROR(AVERAGE(OFFSET('DATOS CORREGIDOS'!$G$6,(((ROW()-27)*24)+24)+432,0,24,1)),"") | E13: 75 | F13: =+IF(B13>E13,"NO","SÍ") -> NO | G13: 37 | H13: =+IF(C13>G13,"NO","SÍ") -> NO | I13: 50 | J13: =+IF(D13>I13,"NO","SÍ") -> NO
A14: =IFERROR(AVERAGE(OFFSET('DATOS CORREGIDOS'!$A$6,(((ROW()-27)*24)+24)+432,0,24,1)),"") | B14: =IFERROR(AVERAGE(OFFSET('DATOS CORREGIDOS'!$E$6,(((ROW()-27)*24)+24)+432,0,24,1)),"") | C14: =IFERROR(AVERAGE(OFFSET('DATOS CORREGIDOS'!$F$6,(((ROW()-27)*24)+24)+432,0,24,1)),"") | D14: =IFERROR(AVERAGE(OFFSET('DATOS CORREGIDOS'!$G$6,(((ROW()-27)*24)+24)+432,0,24,1)),"") | E14: 75 | F14: =+IF(B14>E14,"NO","SÍ") -> NO | G14: 37 | H14: =+IF(C14>G14,"NO","SÍ") -> NO | I14: 50 | J14: =+IF(D14>I14,"NO","SÍ") -> NO
A15: =IFERROR(AVERAGE(OFFSET('DATOS CORREGIDOS'!$A$6,(((ROW()-27)*24)+24)+432,0,24,1)),"") | B15: =IFERROR(AVERAGE(OFFSET('DATOS CORREGIDOS'!$E$6,(((ROW()-27)*24)+24)+432,0,24,1)),"") | C15: =IFERROR(AVERAGE(OFFSET('DATOS CORREGIDOS'!$F$6,(((ROW()-27)*24)+24)+432,0,24,1)),"") | D15: =IFERROR(AVERAGE(OFFSET('DATOS CORREGIDOS'!$G$6,(((ROW()-27)*24)+24)+432,0,24,1)),"") | E15: 75 | F15: =+IF(B15>E15,"NO","SÍ") -> NO | G15: 37 | H15: =+IF(C15>G15,"NO","SÍ") -> NO | I15: 50 | J15: =+IF(D15>I15,"NO","SÍ") -> NO
A16: =IFERROR(AVERAGE(OFFSET('DATOS CORREGIDOS'!$A$6,(((ROW()-27)*24)+24)+432,0,24,1)),"") | B16: =IFERROR(AVERAGE(OFFSET('DATOS CORREGIDOS'!$E$6,(((ROW()-27)*24)+24)+432,0,24,1)),"") | C16: =IFERROR(AVERAGE(OFFSET('DATOS CORREGIDOS'!$F$6,(((ROW()-27)*24)+24)+432,0,24,1)),"") | D16: =IFERROR(AVERAGE(OFFSET('DATOS CORREGIDOS'!$G$6,(((ROW()-27)*24)+24)+432,0,24,1)),"") | E16: 75 | F16: =+IF(B16>E16,"NO","SÍ") -> NO | G16: 37 | H16: =+IF(C16>G16,"NO","SÍ") -> NO | I16: 50 | J16: =+IF(D16>I16,"NO","SÍ") -> NO
A17: =IFERROR(AVERAGE(OFFSET('DATOS CORREGIDOS'!$A$6,(((ROW()-27)*24)+24)+432,0,24,1)),"") | B17: =IFERROR(AVERAGE(OFFSET('DATOS CORREGIDOS'!$E$6,(((ROW()-27)*24)+24)+432,0,24,1)),"") | C17: =IFERROR(AVERAGE(OFFSET('DATOS CORREGIDOS'!$F$6,(((ROW()-27)*24)+24)+432,0,24,1)),"") | D17: =IFERROR(AVERAGE(OFFSET('DATOS CORREGIDOS'!$G$6,(((ROW()-27)*24)+24)+432,0,24,1)),"") | E17: 75 | F17: =+IF(B17>E17,"NO","SÍ") -> NO | G17: 37 | H17: =+IF(C17>G17,"NO","SÍ") -> NO | I17: 50 | J17: =+IF(D17>I17,"NO","SÍ") -> NO
A18: =IFERROR(AVERAGE(OFFSET('DATOS CORREGIDOS'!$A$6,(((ROW()-27)*24)+24)+432,0,24,1)),"") | B18: =IFERROR(AVERAGE(OFFSET('DATOS CORREGIDOS'!$E$6,(((ROW()-27)*24)+24)+432,0,24,1)),"") | C18: =IFERROR(AVERAGE(OFFSET('DATOS CORREGIDOS'!$F$6,(((ROW()-27)*24)+24)+432,0,24,1)),"") | D18: =IFERROR(AVERAGE(OFFSET('DATOS CORREGIDOS'!$G$6,(((ROW()-27)*24)+24)+432,0,24,1)),"") | E18: 75 | F18: =+IF(B18>E18,"NO","SÍ") -> NO | G18: 37 | H18: =+IF(C18>G18,"NO","SÍ") -> NO | I18: 50 | J18: =+IF(D18>I18,"NO","SÍ") -> NO
A19: =IFERROR(AVERAGE(OFFSET('DATOS CORREGIDOS'!$A$6,(((ROW()-27)*24)+24)+432,0,24,1)),"") | B19: =IFERROR(AVERAGE(OFFSET('DATOS CORREGIDOS'!$E$6,(((ROW()-27)*24)+24)+432,0,24,1)),"") | C19: =IFERROR(AVERAGE(OFFSET('DATOS CORREGIDOS'!$F$6,(((ROW()-27)*24)+24)+432,0,24,1)),"") | D19: =IFERROR(AVERAGE(OFFSET('DATOS CORREGIDOS'!$G$6,(((ROW()-27)*24)+24)+432,0,24,1)),"") | E19: 75 | F19: =+IF(B19>E19,"NO","SÍ") -> NO | G19: 37 | H19: =+IF(C19>G19,"NO","SÍ") -> NO | I19: 50 | J19: =+IF(D19>I19,"NO","SÍ") -> NO
... A39: =IFERROR(AVERAGE(OFFSET('DATOS CORREGIDOS'!$A$6,(((ROW()-27)*24)+24)+432,0,24,1)),"") | B39: =IFERROR(AVERAGE(OFFSET('DATOS CORREGIDOS'!$E$6,(((ROW()-27)*24)+24)+432,0,24,1)),"") | C39: =IFERROR(AVERAGE(OFFSET('DATOS CORREGIDOS'!$F$6,(((ROW()-27)*24)+24)+432,0,24,1)),"") | D39: =IFERROR(AVERAGE(OFFSET('DATOS CORREGIDOS'!$G$6,(((ROW()-27)*24)+24)+432,0,24,1)),"") | E39: 75 | F39: =+IF(B39>E39,"NO","SÍ") -> NO | G39: 37 | H39: =+IF(C39>G39,"NO","SÍ") -> NO | I39: 50 | J39: =+IF(D39>I39,"NO","SÍ") -> NO

Sheet COMPARACIÓN 1H
C1: ='COMPARACIÓN 24H'!C1:H3 -> PROCESAMIENTO DE EQUIPOS AUTOMATICOS CALIDAD DE AIRE | J1: Codigo: FO-PO-PSM-66-06
J2: Versiòn: 01
J3: Fecha : 26/08/2023 | M3: Parámetro | N3: # Datos válidos | O3: Datos < Norma 1h | Q3: Datos > Norma 1h
A4: COMPARACION CON NORMA 1 HORA | O4: Cantidad | P4: % | Q4: Cantidad | R4: %
A5: Fecha | B5: #HHMM | C5: PROMEDIOS 1 HORA | F5: LÍMITES NORMATIVOS RES. 2254/2017 | M5: SO2 | N5: =+COUNT(C8:C751) -> 0 | O5: =+N5*P5 -> #DIV/0! | P5: =+COUNTIF(G8:G751,"SÍ")/N5 -> #DIV/0! | Q5: =+N5*R5 -> #DIV/0! | R5: =1-P5 -> #DIV/0!
C6: SO2 (µg/m³) | D6: CO (µg/m³) | E6: NO2 (µg/m³) | F6: SO2 | H6: CO | J6: NO2 | M6: CO | N6: =+COUNT(D8:D751) -> 0 | O6: =+N6*P6 -> #DIV/0! | P6: =+COUNTIF(I8:I751,"SÍ")/N6 -> #DIV/0! | Q6: =+N6*R6 -> #DIV/0! | R6: =1-P6 -> #DIV/0!
F7: Norma 1h (µg/m³) | G7: Cumplimiento | H7: Norma 1h (µg/m³) | I7: Cumplimiento | J7: Norma 1h (µg/m³) | K7: Cumplimiento | M7: NO2 | N7: =+COUNT(E8:E751) -> 0 | O7: =+N7*P7 -> #DIV/0! | P7: =+COUNTIF(K8:K751,"SÍ")/N7 -> #DIV/0! | Q7: =+N7*R7 -> #DIV/0! | R7: =1-P7 -> #DIV/0!
A8: ='DATOS CORREGIDOS'!A30 -> 0 | B8: 1 | C8: =+'DATOS CORREGIDOS'!G30 -> - | D8: =+'DATOS CORREGIDOS'!H30 -> - | E8: =+'DATOS CORREGIDOS'!J30 -> - | F8: 100 | G8: =IF(C8="-","",IF(C8>F8,"NO","SÍ")) | H8: 35000 | I8: =IF(D8="-","",IF(D8>H8,"NO","SÍ")) | J8: 200 | K8: =IF(E8="-","",IF(E8>J8,"NO","SÍ"))
A9: ='DATOS CORREGIDOS'!A31 -> 0 | B9: 1.0416667 | C9: =+'DATOS CORREGIDOS'!G31 -> - | D9: =+'DATOS CORREGIDOS'!H31 -> - | E9: =+'DATOS CORREGIDOS'!J31 -> - | F9: 100 | G9: =IF(C9="-","",IF(C9>F9,"NO","SÍ")) | H9: 35000 | I9: =IF(D9="-","",IF(D9>H9,"NO","SÍ")) | J9: 200 | K9: =IF(E9="-","",IF(E9>J9,"NO","SÍ"))
A10: ='DATOS CORREGIDOS'!A32 -> 0 | B10: 1.0833333 | C10: =+'DATOS CORREGIDOS'!G32 -> - | D10: =+'DATOS CORREGIDOS'!H32 -> - | E10: =+'DATOS CORREGIDOS'!J32 -> - | F10: 100 | G10: =IF(C10="-","",IF(C10>F10,"NO","SÍ")) | H10: 35000 | I10: =IF(D10="-","",IF(D10>H10,"NO","SÍ")) | J10: 200 | K10: =IF(E10="-","",IF(E10>J10,"NO","SÍ"))
A11: ='DATOS CORREGIDOS'!A33 -> 0 | B11: 1.125 | C11: =+'DATOS CORREGIDOS'!G33 -> - | D11: =+'DATOS CORREGIDOS'!H33 -> - | E11: =+'DATOS CORREGIDOS'!J33 -> - | F11: 100 | G11: =IF(C11="-","",IF(C11>F11,"NO","SÍ")) | H11: 35000 | I11: =IF(D11="-","",IF(D11>H11,"NO","SÍ")) | J11: 200 | K11: =IF(E11="-","",IF(E11>J11,"NO","SÍ"))
A12: ='DATOS CORREGIDOS'!A34 -> 0 | B12: 1.1666667 | C12: =+'DATOS CORREGIDOS'!G34 -> - | D12: =+'DATOS CORREGIDOS'!H34 -> - | E12: =+'DATOS CORREGIDOS'!J34 -> - | F12: 100 | G12: =IF(C12="-","",IF(C12>F12,"NO","SÍ")) | H12: 35000 | I12: =IF(D12="-","",IF(D12>H12,"NO","SÍ")) | J12: 200 | K12: =IF(E12="-","",IF(E12>J12,"NO","SÍ"))
A13: ='DATOS CORREGIDOS'!A35 -> 0 | B13: 1.2083333 | C13: =+'DATOS CORREGIDOS'!G35 -> - | D13: =+'DATOS CORREGIDOS'!H35 -> - | E13: =+'DATOS CORREGIDOS'!J35 -> - | F13: 100 | G13: =IF(C13="-","",IF(C13>F13,"NO","SÍ")) | H13: 35000 | I13: =IF(D13="-","",IF(D13>H13,"NO","SÍ")) | J13: 200 | K13: =IF(E13="-","",IF(E13>J13,"NO","SÍ"))
A14: ='DATOS CORREGIDOS'!A36 -> 0 | B14: 1.25 | C14: =+'DATOS CORREGIDOS'!G36 -> - | D14: =+'DATOS CORREGIDOS'!H36 -> - | E14: =+'DATOS CORREGIDOS'!J36 -> - | F14: 100 | G14: =IF(C14="-","",IF(C14>F14,"NO","SÍ")) | H14: 35000 | I14: =IF(D14="-","",IF(D14>H14,"NO","SÍ")) | J14: 200 | K14: =IF(E14="-","",IF(E14>J14,"NO","SÍ"))
A15: ='DATOS CORREGIDOS'!A37 -> 0 | B15: 1.2916667 | C15: =+'DATOS CORREGIDOS'!G37 -> - | D15: =+'DATOS CORREGIDOS'!H37 -> - | E15: =+'DATOS CORREGIDOS'!J37 -> - | F15: 100 | G15: =IF(C15="-","",IF(C15>F15,"NO","SÍ")) | H15: 35000 | I15: =IF(D15="-","",IF(D15>H15,"NO","SÍ")) | J15: 200 | K15: =IF(E15="-","",IF(E15>J15,"NO","SÍ"))
A16: ='DATOS CORREGIDOS'!A38 -> 0 | B16: 1.3333333 | C16: =+'DATOS CORREGIDOS'!G38 -> - | D16: =+'DATOS CORREGIDOS'!H38 -> - | E16: =+'DATOS CORREGIDOS'!J38 -> - | F16: 100 | G16: =IF(C16="-","",IF(C16>F16,"NO","SÍ")) | H16: 35000 | I16: =IF(D16="-","",IF(D16>H16,"NO","SÍ")) | J16: 200 | K16: =IF(E16="-","",IF(E16>J16,"NO","SÍ"))
A17: ='DATOS CORREGIDOS'!A39 -> 0 | B17: 1.375 | C17: =+'DATOS CORREGIDOS'!G39 -> - | D17: =+'DATOS CORREGIDOS'!H39 -> - | E17: =+'DATOS CORREGIDOS'!J39 -> - | F17: 100 | G17: =IF(C17="-","",IF(C17>F17,"NO","SÍ")) | H17: 35000 | I17: =IF(D17="-","",IF(D17>H17,"NO","SÍ")) | J17: 200 | K17: =IF(E17="-","",IF(E17>J17,"NO","SÍ"))
A18: ='DATOS CORREGIDOS'!A40 -> 0 | B18: 1.4166667 | C18: =+'DATOS CORREGIDOS'!G40 -> - | D18: =+'DATOS CORREGIDOS'!H40 -> - | E18: =+'DATOS CORREGIDOS'!J40 -> - | F18: 100 | G18: =IF(C18="-","",IF(C18>F18,"NO","SÍ")) | H18: 35000 | I18: =IF(D18="-","",IF(D18>H18,"NO","SÍ")) | J18: 200 | K18: =IF(E18="-","",IF(E18>J18,"NO","SÍ"))
A19: ='DATOS CORREGIDOS'!A41 -> 0 | B19: 1.4583333 | C19: =+'DATOS CORREGIDOS'!G41 -> - | D19: =+'DATOS CORREGIDOS'!H41 -> - | E19: =+'DATOS CORREGIDOS'!J41 -> - | F19: 100 | G19: =IF(C19="-","",IF(C19>F19,"NO","SÍ")) | H19: 35000 | I19: =IF(D19="-","",IF(D19>H19,"NO","SÍ")) | J19: 200 | K19: =IF(E19="-","",IF(E19>J19,"NO","SÍ"))
... A751: ='DATOS CORREGIDOS'!A773 -> 0 | B751: 31.958333 | C751: =+'DATOS CORREGIDOS'!G773 -> - | D751: =+'DATOS CORREGIDOS'!H773 -> - | E751: =+'DATOS CORREGIDOS'!J773 -> - | F751: 100 | G751: =IF(C751="-","",IF(C751>F751,"NO","SÍ")) | H751: 35000 | I751: =IF(D751="-","",IF(D751>H751,"NO","SÍ")) | J751: 200 | K751: =IF(E751="-","",IF(E751>J751,"NO","SÍ"))

Sheet COMPARACIÓN 8H
E1: ='COMPARACIÓN 1H'!$C$1 -> PROCESAMIENTO DE EQUIPOS AUTOMATICOS CALIDAD DE AIRE | I1: Codigo: FO-PO-PSM-66-06
I2: Versiòn: 01
I3: Fecha : 26/08/2023
A4: COMPARACION CON NORMA 8 HORAS | L4: Parámetro | M4: # Datos válidos | N4: Datos < Norma 8h | P4: Datos > Norma 8h
A5: Fecha | B5: Media Móvil 8h | E5: PROMEDIOS 8 HORAS | G5: LÍMITES NORMATIVOS RES. 2254/2017 | N5: Cantidad | O5: % | P5: Cantidad | Q5: %
E6: CO (µg/m³) | F6: O3 (µg/m³) | G6: CO | I6: O3 | L6: CO | M6: =+COUNT(E25:E768) -> 0 | N6: =+M6*O6 -> #DIV/0! | O6: =+COUNTIF(H8:H720,"SÍ")/M6 -> #DIV/0! | P6: =+M6*Q6 -> #DIV/0! | Q6: =1-O6 -> #DIV/0!
G7: Norma 8h (µg/m³) | H7: Cumplimiento | I7: Norma 8h (µg/m³) | J7: Cumplimiento | L7: O3 | M7: =+COUNT(F25:F768) -> 0 | N7: =+M7*O7 -> #DIV/0! | O7: =+COUNTIF(J8:J720,"SÍ")/M7 -> #DIV/0! | P7: =+M7*Q7 -> #DIV/0! | Q7: =1-O7 -> #DIV/0!
A8: ='DATOS CORREGIDOS'!A13 -> 0 | B8: 0 | C8: - | D8: 0.29166667 | E8: =IF(ISBLANK(A8),"",AVERAGE('DATOS CORREGIDOS'!H6:H13)) -> #DIV/0! | F8: =IF(ISBLANK(A8),"",AVERAGE('DATOS CORREGIDOS'!I6:I13)) -> #DIV/0! | G8: 5000 | H8: =IF(E8="-","",IF(E8>G8,"NO","SÍ")) -> #DIV/0! | I8: 100 | J8: =IF(F8="-","",IF(F8>I8,"NO","SÍ")) -> #DIV/0!
A9: ='DATOS CORREGIDOS'!A14 -> 0 | B9: 0.041666667 | C9: - | D9: =+$B$9+D8 -> 0.33333333 | E9: =IF(ISBLANK(A9),"",AVERAGE('DATOS CORREGIDOS'!H7:H14)) -> #DIV/0! | F9: =IF(ISBLANK(A9),"",AVERAGE('DATOS CORREGIDOS'!I7:I14)) -> #DIV/0! | G9: 5000 | H9: =IF(E9="-","",IF(E9>G9,"NO","SÍ")) -> #DIV/0! | I9: 100 | J9: =IF(F9="-","",IF(F9>I9,"NO","SÍ")) -> #DIV/0!
A10: ='DATOS CORREGIDOS'!A15 -> 0 | B10: =+$B$9+B9 -> 0.083333333 | C10: - | D10: =+$B$9+D9 -> 0.375 | E10: =IF(ISBLANK(A10),"",AVERAGE('DATOS CORREGIDOS'!H8:H15)) -> #DIV/0! | F10: =IF(ISBLANK(A10),"",AVERAGE('DATOS CORREGIDOS'!I8:I15)) -> #DIV/0! | G10: 5000 | H10: =IF(E10="-","",IF(E10>G10,"NO","SÍ")) -> #DIV/0! | I10: 100 | J10: =IF(F10="-","",IF(F10>I10,"NO","SÍ")) -> #DIV/0!
A11: ='DATOS CORREGIDOS'!A16 -> 0 | B11: =+$B$9+B10 -> 0.125 | C11: - | D11: =+$B$9+D10 -> 0.41666667 | E11: =IF(ISBLANK(A11),"",AVERAGE('DATOS CORREGIDOS'!H9:H16)) -> #DIV/0! | F11: =IF(ISBLANK(A11),"",AVERAGE('DATOS CORREGIDOS'!I9:I16)) -> #DIV/0! | G11: 5000 | H11: =IF(E11="-","",IF(E11>G11,"NO","SÍ")) -> #DIV/0! | I11: 100 | J11: =IF(F11="-","",IF(F11>I11,"NO","SÍ")) -> #DIV/0!
A12: ='DATOS CORREGIDOS'!A17 -> 0 | B12: =+$B$9+B11 -> 0.16666667 | C12: - | D12: =+$B$9+D11 -> 0.45833333 | E12: =IF(ISBLANK(A12),"",AVERAGE('DATOS CORREGIDOS'!H10:H17)) -> #DIV/0! | F12: =IF(ISBLANK(A12),"",AVERAGE('DATOS CORREGIDOS'!I10:I17)) -> #DIV/0! | G12: 5000 | H12: =IF(E12="-","",IF(E12>G12,"NO","SÍ")) -> #DIV/0! | I12: 100 | J12: =IF(F12="-","",IF(F12>I12,"NO","SÍ")) -> #DIV/0!
A13: ='DATOS CORREGIDOS'!A18 -> 0 | B13: =+$B$9+B12 -> 0.20833333 | C13: - | D13: =+$B$9+D12 -> 0.5 | E13: =IF(ISBLANK(A13),"",AVERAGE('DATOS CORREGIDOS'!H11:H18)) -> #DIV/0! | F13: =IF(ISBLANK(A13),"",AVERAGE('DATOS CORREGIDOS'!I11:I18)) -> #DIV/0! | G13: 5000 | H13: =IF(E13="-","",IF(E13>G13,"NO","SÍ")) -> #DIV/0! | I13: 100 | J13: =IF(F13="-","",IF(F13>I13,"NO","SÍ")) -> #DIV/0!
A14: ='DATOS CORREGIDOS'!A19 -> 0 | B14: =+$B$9+B13 -> 0.25 | C14: - | D14: =+$B$9+D13 -> 0.54166667 | E14: =IF(ISBLANK(A14),"",AVERAGE('DATOS CORREGIDOS'!H12:H19)) -> #DIV/0! | F14: =IF(ISBLANK(A14),"",AVERAGE('DATOS CORREGIDOS'!I12:I19)) -> #DIV/0! | G14: 5000 | H14: =IF(E14="-","",IF(E14>G14,"NO","SÍ")) -> #DIV/0! | I14: 100 | J14: =IF(F14="-","",IF(F14>I14,"NO","SÍ")) -> #DIV/0!
A15: ='DATOS CORREGIDOS'!A20 -> 0 | B15: =+$B$9+B14 -> 0.29166667 | C15: - | D15: =+$B$9+D14 -> 0.58333333 | E15: =IF(ISBLANK(A15),"",AVERAGE('DATOS CORREGIDOS'!H13:H20)) -> #DIV/0! | F15: =IF(ISBLANK(A15),"",AVERAGE('DATOS CORREGIDOS'!I13:I20)) -> #DIV/0! | G15: 5000 | H15: =IF(E15="-","",IF(E15>G15,"NO","SÍ")) -> #DIV/0! | I15: 100 | J15: =IF(F15="-","",IF(F15>I15,"NO","SÍ")) -> #DIV/0!
A16: ='DATOS CORREGIDOS'!A21 -> 0 | B16: =+$B$9+B15 -> 0.33333333 | C16: - | D16: =+$B$9+D15 -> 0.625 | E16: =IF(ISBLANK(A16),"",AVERAGE('DATOS CORREGIDOS'!H14:H21)) -> #DIV/0! | F16: =IF(ISBLANK(A16),"",AVERAGE('DATOS CORREGIDOS'!I14:I21)) -> #DIV/0! | G16: 5000 | H16: =IF(E16="-","",IF(E16>G16,"NO","SÍ")) -> #DIV/0! | I16: 100 | J16: =IF(F16="-","",IF(F16>I16,"NO","SÍ")) -> #DIV/0!
A17: ='DATOS CORREGIDOS'!A22 -> 0 | B17: =+$B$9+B16 -> 0.375 | C17: - | D17: =+$B$9+D16 -> 0.66666667 | E17: =IF(ISBLANK(A17),"",AVERAGE('DATOS CORREGIDOS'!H15:H22)) -> #DIV/0! | F17: =IF(ISBLANK(A17),"",AVERAGE('DATOS CORREGIDOS'!I15:I22)) -> #DIV/0! | G17: 5000 | H17: =IF(E17="-","",IF(E17>G17,"NO","SÍ")) -> #DIV/0! | I17: 100 | J17: =IF(F17="-","",IF(F17>I17,"NO","SÍ")) -> #DIV/0!
A18: ='DATOS CORREGIDOS'!A23 -> 0 | B18: =+$B$9+B17 -> 0.41666667 | C18: - | D18: =+$B$9+D17 -> 0.70833333 | E18: =IF(ISBLANK(A18),"",AVERAGE('DATOS CORREGIDOS'!H16:H23)) -> #DIV/0! | F18: =IF(ISBLANK(A18),"",AVERAGE('DATOS CORREGIDOS'!I16:I23)) -> #DIV/0! | G18: 5000 | H18: =IF(E18="-","",IF(E18>G18,"NO","SÍ")) -> #DIV/0! | I18: 100 | J18: =IF(F18="-","",IF(F18>I18,"NO","SÍ")) -> #DIV/0!
A19: ='DATOS CORREGIDOS'!A24 -> 0 | B19: =+$B$9+B18 -> 0.45833333 | C19: - | D19: =+$B$9+D18 -> 0.75 | E19: =IF(ISBLANK(A19),"",AVERAGE('DATOS CORREGIDOS'!H17:H24)) -> #DIV/0! | F19: =IF(ISBLANK(A19),"",AVERAGE('DATOS CORREGIDOS'!I17:I24)) -> #DIV/0! | G19: 5000 | H19: =IF(E19="-","",IF(E19>G19,"NO","SÍ")) -> #DIV/0! | I19: 100 | J19: =IF(F19="-","",IF(F19>I19,"NO","SÍ")) -> #DIV/0!
A20: ='DATOS CORREGIDOS'!A25 -> 0 | B20: =+$B$9+B19 -> 0.5 | C20: - | D20: =+$B$9+D19 -> 0.79166667 | E20: =IF(ISBLANK(A20),"",AVERAGE('DATOS CORREGIDOS'!H18:H25)) -> #DIV/0! | F20: =IF(ISBLANK(A20),"",AVERAGE('DATOS CORREGIDOS'!I18:I25)) -> #DIV/0! | G20: 5000 | H20: =IF(E20="-","",IF(E20>G20,"NO","SÍ")) -> #DIV/0! | I20: 100 | J20: =IF(F20="-","",IF(F20>I20,"NO","SÍ")) -> #DIV/0!
A21: ='DATOS CORREGIDOS'!A26 -> 0 | B21: =+$B$9+B20 -> 0.54166667 | C21: - | D21: =+$B$9+D20 -> 0.83333333 | E21: =IF(ISBLANK(A21),"",AVERAGE('DATOS CORREGIDOS'!H19:H26)) -> #DIV/0! | F21: =IF(ISBLANK(A21),"",AVERAGE('DATOS CORREGIDOS'!I19:I26)) -> #DIV/0! | G21: 5000 | H21: =IF(E21="-","",IF(E21>G21,"NO","SÍ")) -> #DIV/0! | I21: 100 | J21: =IF(F21="-","",IF(F21>I21,"NO","SÍ")) -> #DIV/0!
... A720: ='DATOS CORREGIDOS'!A725 -> 0 | B720: =+$B$9+B719 -> 29.666667 | C720: - | D720: =+$B$9+D719 -> 29.958333 | E720: =IF(ISBLANK(A720),"",AVERAGE('DATOS CORREGIDOS'!H718:H725)) -> #DIV/0! | F720: =IF(ISBLANK(A720),"",AVERAGE('DATOS CORREGIDOS'!I718:I725)) -> #DIV/0! | G720: 5000 | H720: =IF(E720="-","",IF(E720>G720,"NO","SÍ")) -> #DIV/0! | I720: 100 | J720: =IF(F720="-","",IF(F720>I720,"NO","SÍ")) -> #DIV/0!
A721: ='DATOS CORREGIDOS'!A726 -> 0 | B721: =+$B$9+B720 -> 29.708333 | C721: - | D721: =+$B$9+D720 -> 30 | E721: =IF(ISBLANK(A721),"",AVERAGE('DATOS CORREGIDOS'!H719:H725)) -> #DIV/0! | F721: =IF(ISBLANK(A721),"",AVERAGE('DATOS CORREGIDOS'!I719:I725)) -> #DIV/0! | G721: 5000 | H721: =IF(E721="-","",IF(E721>G721,"NO","SÍ")) -> #DIV/0! | I721: 100 | J721: =IF(F721="-","",IF(F721>I721,"NO","SÍ")) -> #DIV/0!
A722: ='DATOS CORREGIDOS'!A727 -> 0 | B722: =+$B$9+B721 -> 29.75 | C722: - | D722: =+$B$9+D721 -> 30.041667 | E722: =IF(ISBLANK(A722),"",AVERAGE('DATOS CORREGIDOS'!H720:H725)) -> #DIV/0! | F722: =IF(ISBLANK(A722),"",AVERAGE('DATOS CORREGIDOS'!I720:I725)) -> #DIV/0! | G722: 5000 | H722: =IF(E722="-","",IF(E722>G722,"NO","SÍ")) -> #DIV/0! | I722: 100 | J722: =IF(F722="-","",IF(F722>I722,"NO","SÍ")) -> #DIV/0!
A723: ='DATOS CORREGIDOS'!A728 -> 0 | B723: =+$B$9+B722 -> 29.791667 | C723: - | D723: =+$B$9+D722 -> 30.083333 | E723: =IF(ISBLANK(A723),"",AVERAGE('DATOS CORREGIDOS'!H721:H725)) -> #DIV/0! | F723: =IF(ISBLANK(A723),"",AVERAGE('DATOS CORREGIDOS'!I721:I725)) -> #DIV/0! | G723: 5000 | H723: =IF(E723="-","",IF(E723>G723,"NO","SÍ")) -> #DIV/0! | I723: 100 | J723: =IF(F723="-","",IF(F723>I723,"NO","SÍ")) -> #DIV/0!
A724: ='DATOS CORREGIDOS'!A729 -> 0 | B724: =+$B$9+B723 -> 29.833333 | C724: - | D724: =+$B$9+D723 -> 30.125 | E724: =IF(ISBLANK(A724),"",AVERAGE('DATOS CORREGIDOS'!H722:H725)) -> #DIV/0! | F724: =IF(ISBLANK(A724),"",AVERAGE('DATOS CORREGIDOS'!I722:I725)) -> #DIV/0! | G724: 5000 | H724: =IF(E724="-","",IF(E724>G724,"NO","SÍ")) -> #DIV/0! | I724: 100 | J724: =IF(F724="-","",IF(F724>I724,"NO","SÍ")) -> #DIV/0!
A725: ='DATOS CORREGIDOS'!A730 -> 0 | B725: =+$B$9+B724 -> 29.875 | C725: - | D725: =+$B$9+D724 -> 30.166667 | E725: =IF(ISBLANK(A725),"",AVERAGE('DATOS CORREGIDOS'!H723:H725)) -> #DIV/0! | F725: =IF(ISBLANK(A725),"",AVERAGE('DATOS CORREGIDOS'!I723:I725)) -> #DIV/0! | G725: 5000 | H725: =IF(E725="-","",IF(E725>G725,"NO","SÍ")) -> #DIV/0! | I725: 100 | J725: =IF(F725="-","",IF(F725>I725,"NO","SÍ")) -> #DIV/0!
A726: ='DATOS CORREGIDOS'!A731 -> 0 | B726: =+$B$9+B725 -> 29.916667 | C726: - | D726: =+$B$9+D725 -> 30.208333 | E726: =IF(ISBLANK(A726),"",AVERAGE('DATOS CORREGIDOS'!H724:H725)) -> #DIV/0! | F726: =IF(ISBLANK(A726),"",AVERAGE('DATOS CORREGIDOS'!I724:I725)) -> #DIV/0! | G726: 5000 | H726: =IF(E726="-","",IF(E726>G726,"NO","SÍ")) -> #DIV/0! | I726: 100 | J726: =IF(F726="-","",IF(F726>I726,"NO","SÍ")) -> #DIV/0!
A727: ='DATOS CORREGIDOS'!A732 -> 0 | B727: =+$B$9+B726 -> 29.958333 | C727: - | D727: =+$B$9+D726 -> 30.25 | E727: =IF(ISBLANK(A727),"",AVERAGE('DATOS CORREGIDOS'!H725:H725)) -> #DIV/0! | F727: =IF(ISBLANK(A727),"",AVERAGE('DATOS CORREGIDOS'!I725:I725)) -> #DIV/0! | G727: 5000 | H727: =IF(E727="-","",IF(E727>G727,"NO","SÍ")) -> #DIV/0! | I727: 100 | J727: =IF(F727="-","",IF(F727>I727,"NO","SÍ")) -> #DIV/0!
A728: ='DATOS CORREGIDOS'!A733 -> 0 | B728: =+$B$9+B727 -> 30 | C728: - | D728: =+$B$9+D727 -> 30.291667 | E728: =IF(ISBLANK(A728),"",AVERAGE('DATOS CORREGIDOS'!H726:H726)) -> #DIV/0! | F728: =IF(ISBLANK(A728),"",AVERAGE('DATOS CORREGIDOS'!I726:I726)) -> #DIV/0! | G728: 5001 | H728: =IF(E728="-","",IF(E728>G728,"NO","SÍ")) -> #DIV/0! | I728: 101 | J728: =IF(F728="-","",IF(F728>I728,"NO","SÍ")) -> #DIV/0!
A729: ='DATOS CORREGIDOS'!A734 -> 0 | B729: =+$B$9+B728 -> 30.041667 | C729: - | D729: =+$B$9+D728 -> 30.333333 | E729: =IF(ISBLANK(A729),"",AVERAGE('DATOS CORREGIDOS'!H727:H727)) -> #DIV/0! | F729: =IF(ISBLANK(A729),"",AVERAGE('DATOS CORREGIDOS'!I727:I727)) -> #DIV/0! | G729: 5000 | H729: =IF(E729="-","",IF(E729>G729,"NO","SÍ")) -> #DIV/0! | I729: 100 | J729: =IF(F729="-","",IF(F729>I729,"NO","SÍ")) -> #DIV/0!
A730: ='DATOS CORREGIDOS'!A735 -> 0 | B730: =+$B$9+B729 -> 30.083333 | C730: - | D730: =+$B$9+D729 -> 30.375 | E730: =IF(ISBLANK(A730),"",AVERAGE('DATOS CORREGIDOS'!H728:H728)) -> #DIV/0! | F730: =IF(ISBLANK(A730),"",AVERAGE('DATOS CORREGIDOS'!I728:I728)) -> #DIV/0! | G730: 5000 | H730: =IF(E730="-","",IF(E730>G730,"NO","SÍ")) -> #DIV/0! | I730: 100 | J730: =IF(F730="-","",IF(F730>I730,"NO","SÍ")) -> #DIV/0!
A731: ='DATOS CORREGIDOS'!A736 -> 0 | B731: =+$B$9+B730 -> 30.125 | C731: - | D731: =+$B$9+D730 -> 30.416667 | E731: =IF(ISBLANK(A731),"",AVERAGE('DATOS CORREGIDOS'!H729:H729)) -> #DIV/0! | F731: =IF(ISBLANK(A731),"",AVERAGE('DATOS CORREGIDOS'!I729:I729)) -> #DIV/0! | G731: 5000 | H731: =IF(E731="-","",IF(E731>G731,"NO","SÍ")) -> #DIV/0! | I731: 100 | J731: =IF(F731="-","",IF(F731>I731,"NO","SÍ")) -> #DIV/0!
A732: ='DATOS CORREGIDOS'!A737 -> 0 | B732: =+$B$9+B731 -> 30.166667 | C732: - | D732: =+$B$9+D731 -> 30.458333 | E732: =IF(ISBLANK(A732),"",AVERAGE('DATOS CORREGIDOS'!H730:H730)) -> #DIV/0! | F732: =IF(ISBLANK(A732),"",AVERAGE('DATOS CORREGIDOS'!I730:I730)) -> #DIV/0! | G732: 5000 | H732: =IF(E732="-","",IF(E732>G732,"NO","SÍ")) -> #DIV/0! | I732: 100 | J732: =IF(F732="-","",IF(F732>I732,"NO","SÍ")) -> #DIV/0!
A733: ='DATOS CORREGIDOS'!A738 -> 0 | B733: =+$B$9+B732 -> 30.208333 | C733: - | D733: =+$B$9+D732 -> 30.5 | E733: =IF(ISBLANK(A733),"",AVERAGE('DATOS CORREGIDOS'!H731:H731)) -> #DIV/0! | F733: =IF(ISBLANK(A733),"",AVERAGE('DATOS CORREGIDOS'!I731:I731)) -> #DIV/0! | G733: 5000 | H733: =IF(E733="-","",IF(E733>G733,"NO","SÍ")) -> #DIV/0! | I733: 100 | J733: =IF(F733="-","",IF(F733>I733,"NO","SÍ")) -> #DIV/0!
A734: ='DATOS CORREGIDOS'!A739 -> 0 | B734: =+$B$9+B733 -> 30.25 | C734: - | D734: =+$B$9+D733 -> 30.541667 | E734: =IF(ISBLANK(A734),"",AVERAGE('DATOS CORREGIDOS'!H732:H732)) -> #DIV/0! | F734: =IF(ISBLANK(A734),"",AVERAGE('DATOS CORREGIDOS'!I732:I732)) -> #DIV/0! | G734: 5000 | H734: =IF(E734="-","",IF(E734>G734,"NO","SÍ")) -> #DIV/0! | I734: 100 | J734: =IF(F734="-","",IF(F734>I734,"NO","SÍ")) -> #DIV/0!
A735: ='DATOS CORREGIDOS'!A740 -> 0 | B735: =+$B$9+B734 -> 30.291667 | C735: - | D735: =+$B$9+D734 -> 30.583333 | E735: =IF(ISBLANK(A735),"",AVERAGE('DATOS CORREGIDOS'!H733:H733)) -> #DIV/0! | F735: =IF(ISBLANK(A735),"",AVERAGE('DATOS CORREGIDOS'!I733:I733)) -> #DIV/0! | G735: 5000 | H735: =IF(E735="-","",IF(E735>G735,"NO","SÍ")) -> #DIV/0! | I735: 100 | J735: =IF(F735="-","",IF(F735>I735,"NO","SÍ")) -> #DIV/0!
A736: ='DATOS CORREGIDOS'!A741 -> 0 | B736: =+$B$9+B735 -> 30.333333 | C736: - | D736: =+$B$9+D735 -> 30.625 | E736: =IF(ISBLANK(A736),"",AVERAGE('DATOS CORREGIDOS'!H734:H734)) -> #DIV/0! | F736: =IF(ISBLANK(A736),"",AVERAGE('DATOS CORREGIDOS'!I734:I734)) -> #DIV/0! | G736: 5000 | H736: =IF(E736="-","",IF(E736>G736,"NO","SÍ")) -> #DIV/0! | I736: 100 | J736: =IF(F736="-","",IF(F736>I736,"NO","SÍ")) -> #DIV/0!
A737: ='DATOS CORREGIDOS'!A742 -> 0 | B737: =+$B$9+B736 -> 30.375 | C737: - | D737: =+$B$9+D736 -> 30.666667 | E737: =IF(ISBLANK(A737),"",AVERAGE('DATOS CORREGIDOS'!H735:H735)) -> #DIV/0! | F737: =IF(ISBLANK(A737),"",AVERAGE('DATOS CORREGIDOS'!I735:I735)) -> #DIV/0! | G737: 5000 | H737: =IF(E737="-","",IF(E737>G737,"NO","SÍ")) -> #DIV/0! | I737: 100 | J737: =IF(F737="-","",IF(F737>I737,"NO","SÍ")) -> #DIV/0!
A738: ='DATOS CORREGIDOS'!A743 -> 0 | B738: =+$B$9+B737 -> 30.416667 | C738: - | D738: =+$B$9+D737 -> 30.708333 | E738: =IF(ISBLANK(A738),"",AVERAGE('DATOS CORREGIDOS'!H736:H736)) -> #DIV/0! | F738: =IF(ISBLANK(A738),"",AVERAGE('DATOS CORREGIDOS'!I736:I736)) -> #DIV/0! | G738: 5000 | H738: =IF(E738="-","",IF(E738>G738,"NO","SÍ")) -> #DIV/0! | I738: 100 | J738: =IF(F738="-","",IF(F738>I738,"NO","SÍ")) -> #DIV/0!
...

Sheet ICA 1H-SO2
E2: ='COMPARACIÓN 8H'!E1 -> PROCESAMIENTO DE EQUIPOS AUTOMATICOS CALIDAD DE AIRE | N2: ='COMPARACIÓN 8H'!I1 -> Codigo: FO-PO-PSM-66-06
N3: ='COMPARACIÓN 8H'!I2 -> Versiòn: 01
N4: ='COMPARACIÓN 8H'!I3 -> Fecha : 26/08/2023
K6: Verde | L6: 0 - 50
C7: 0-93 | D7: 94-197 | E7: 198-486 | F7: 847-797 | G7: 798-1583 | H7: 1584-2629 | K7: Amarillo | L7: 51 - 100
B8: Ialto | C8: 50 | D8: 100 | E8: 150 | F8: 200 | G8: 300 | H8: 500 | K8: Naranja | L8: 101 - 150
B9: Ibajo | C9: 0 | D9: 51 | E9: 101 | F9: 151 | G9: 201 | H9: 301 | K9: Rojo | L9: 151 - 200
B10: PCalto | C10: 93 | D10: 197 | E10: 486 | F10: 797 | G10: 1583 | H10: 2629 | K10: Purpura | L10: 201 - 300
B11: PCbajo | C11: 0 | D11: 94 | E11: 198 | F11: 487 | G11: 798 | H11: 1584 | K11: Marron | L11: 301 - 500
C14: Fecha | D14: Estación 1. | G14: Fecha | H14: ICA | I14: Fecha | J14: ICA | K14: Fecha | L14: ICA | M14: Fecha | N14: ICA | O14: Fecha | P14: ICA
C15: ='COMPARACIÓN 1H'!A8 -> 0 | D15: ='COMPARACIÓN 1H'!C8 -> - | G15: =C15 -> 0 | H15: =IF(D15<=$C$10,(((($C$8-$C$9)/($C$10-$C$11))*(D15-$C$11))+$C$9),(IF(D15<=$D$10,(((($D$8-$D$9)/($D$10-$D$11))*(D15-$D$11))+$D$9),IF(D15<=$E$10,(((($E$8-$E$9)/($E$10-$E$11))*(D15-$E$11))+$E$9),IF(D15<=$F$10,(((($F$8-$F$9)/($F$10-$F$11))*(D15-$F$11))+$F$9),IF(D15<=$G$10,(((($G$8-$G$9)/($G$10-$G$11))*(D15-$G$11))+$G$9),((((($H$8-$H$9)/($H$10-$H$11))*(D15-$H$11))+$H$9)))))))) -> #VALUE! | I15: =C165 -> 0 | J15: =IF(D165<=$C$10,(((($C$8-$C$9)/($C$10-$C$11))*(D165-$C$11))+$C$9),(IF(D165<=$D$10,(((($D$8-$D$9)/($D$10-$D$11))*(D165-$D$11))+$D$9),IF(D165<=$E$10,(((($E$8-$E$9)/($E$10-$E$11))*(D165-$E$11))+$E$9),IF(D165<=$F$10,(((($F$8-$F$9)/($F$10-$F$11))*(D165-$F$11))+$F$9),IF(D165<=$G$10,(((($G$8-$G$9)/($G$10-$G$11))*(D165-$G$11))+$G$9),((((($H$8-$H$9)/($H$10-$H$11))*(D165-$H$11))+$H$9)))))))) -> #VALUE! | K15: =C315 -> 0 | L15: =IF(D315<=$C$10,(((($C$8-$C$9)/($C$10-$C$11))*(D315-$C$11))+$C$9),(IF(D315<=$D$10,(((($D$8-$D$9)/($D$10-$D$11))*(D315-$D$11))+$D$9),IF(D315<=$E$10,(((($E$8-$E$9)/($E$10-$E$11))*(D315-$E$11))+$E$9),IF(D315<=$F$10,(((($F$8-$F$9)/($F$10-$F$11))*(D315-$F$11))+$F$9),IF(D315<=$G$10,(((($G$8-$G$9)/($G$10-$G$11))*(D315-$G$11))+$G$9),((((($H$8-$H$9)/($H$10-$H$11))*(D315-$H$11))+$H$9)))))))) -> #VALUE! | M15: =C465 -> 0 | N15: =IF(D465<=$C$10,(((($C$8-$C$9)/($C$10-$C$11))*(D465-$C$11))+$C$9),(IF(D465<=$D$10,(((($D$8-$D$9)/($D$10-$D$11))*(D465-$D$11))+$D$9),IF(D465<=$E$10,(((($E$8-$E$9)/($E$10-$E$11))*(D465-$E$11))+$E$9),IF(D465<=$F$10,(((($F$8-$F$9)/($F$10-$F$11))*(D465-$F$11))+$F$9),IF(D465<=$G$10,(((($G$8-$G$9)/($G$10-$G$11))*(D465-$G$11))+$G$9),((((($H$8-$H$9)/($H$10-$H$11))*(D465-$H$11))+$H$9)))))))) -> #VALUE! | O15: =C615 -> 0 | P15: =IF(D615<=$C$10,(((($C$8-$C$9)/($C$10-$C$11))*(D615-$C$11))+$C$9),(IF(D615<=$D$10,(((($D$8-$D$9)/($D$10-$D$11))*(D615-$D$11))+$D$9),IF(D615<=$E$10,(((($E$8-$E$9)/($E$10-$E$11))*(D615-$E$11))+$E$9),IF(D615<=$F$10,(((($F$8-$F$9)/($F$10-$F$11))*(D615-$F$11))+$F$9),IF(D615<=$G$10,(((($G$8-$G$9)/($G$10-$G$11))*(D615-$G$11))+$G$9),((((($H$8-$H$9)/($H$10-$H$11))*(D615-$H$11))+$H$9)))))))) -> #VALUE! | W15: =+IF(H15<=50.99,$J$712,IF(H15<=100.99,$J$713,IF(H15<=150.99,$J$714,IF(H15<=200.99,$J$715,IF(H15<=300.99,$J$716,IF(H15>300,$J$717,IF(ISTEXT(H15),"Descartada"))))))) -> #VALUE!
C16: ='COMPARACIÓN 1H'!A9 -> 0 | D16: ='COMPARACIÓN 1H'!C9 -> - | G16: =C16 -> 0 | H16: =IF(D16<=$C$10,(((($C$8-$C$9)/($C$10-$C$11))*(D16-$C$11))+$C$9),(IF(D16<=$D$10,(((($D$8-$D$9)/($D$10-$D$11))*(D16-$D$11))+$D$9),IF(D16<=$E$10,(((($E$8-$E$9)/($E$10-$E$11))*(D16-$E$11))+$E$9),IF(D16<=$F$10,(((($F$8-$F$9)/($F$10-$F$11))*(D16-$F$11))+$F$9),IF(D16<=$G$10,(((($G$8-$G$9)/($G$10-$G$11))*(D16-$G$11))+$G$9),((((($H$8-$H$9)/($H$10-$H$11))*(D16-$H$11))+$H$9)))))))) -> #VALUE! | I16: =C166 -> 0 | J16: =IF(D166<=$C$10,(((($C$8-$C$9)/($C$10-$C$11))*(D166-$C$11))+$C$9),(IF(D166<=$D$10,(((($D$8-$D$9)/($D$10-$D$11))*(D166-$D$11))+$D$9),IF(D166<=$E$10,(((($E$8-$E$9)/($E$10-$E$11))*(D166-$E$11))+$E$9),IF(D166<=$F$10,(((($F$8-$F$9)/($F$10-$F$11))*(D166-$F$11))+$F$9),IF(D166<=$G$10,(((($G$8-$G$9)/($G$10-$G$11))*(D166-$G$11))+$G$9),((((($H$8-$H$9)/($H$10-$H$11))*(D166-$H$11))+$H$9)))))))) -> #VALUE! | K16: =C316 -> 0 | L16: =IF(D316<=$C$10,(((($C$8-$C$9)/($C$10-$C$11))*(D316-$C$11))+$C$9),(IF(D316<=$D$10,(((($D$8-$D$9)/($D$10-$D$11))*(D316-$D$11))+$D$9),IF(D316<=$E$10,(((($E$8-$E$9)/($E$10-$E$11))*(D316-$E$11))+$E$9),IF(D316<=$F$10,(((($F$8-$F$9)/($F$10-$F$11))*(D316-$F$11))+$F$9),IF(D316<=$G$10,(((($G$8-$G$9)/($G$10-$G$11))*(D316-$G$11))+$G$9),((((($H$8-$H$9)/($H$10-$H$11))*(D316-$H$11))+$H$9)))))))) -> #VALUE! | M16: =C466 -> 0 | N16: =IF(D466<=$C$10,(((($C$8-$C$9)/($C$10-$C$11))*(D466-$C$11))+$C$9),(IF(D466<=$D$10,(((($D$8-$D$9)/($D$10-$D$11))*(D466-$D$11))+$D$9),IF(D466<=$E$10,(((($E$8-$E$9)/($E$10-$E$11))*(D466-$E$11))+$E$9),IF(D466<=$F$10,(((($F$8-$F$9)/($F$10-$F$11))*(D466-$F$11))+$F$9),IF(D466<=$G$10,(((($G$8-$G$9)/($G$10-$G$11))*(D466-$G$11))+$G$9),((((($H$8-$H$9)/($H$10-$H$11))*(D466-$H$11))+$H$9)))))))) -> #VALUE! | O16: =C616 -> 0 | P16: =IF(D616<=$C$10,(((($C$8-$C$9)/($C$10-$C$11))*(D616-$C$11))+$C$9),(IF(D616<=$D$10,(((($D$8-$D$9)/($D$10-$D$11))*(D616-$D$11))+$D$9),IF(D616<=$E$10,(((($E$8-$E$9)/($E$10-$E$11))*(D616-$E$11))+$E$9),IF(D616<=$F$10,(((($F$8-$F$9)/($F$10-$F$11))*(D616-$F$11))+$F$9),IF(D616<=$G$10,(((($G$8-$G$9)/($G$10-$G$11))*(D616-$G$11))+$G$9),((((($H$8-$H$9)/($H$10-$H$11))*(D616-$H$11))+$H$9)))))))) -> #VALUE! | W16: =+IF(H16<=50.99,$J$712,IF(H16<=100.99,$J$713,IF(H16<=150.99,$J$714,IF(H16<=200.99,$J$715,IF(H16<=300.99,$J$716,IF(H16>300,$J$717,IF(ISTEXT(H16),"Descartada"))))))) -> #VALUE!
